Workbook
Name AA: #REF!
Name AAA: #REF!
Name ACTUAL: #REF!
Name AL: #REF!
Name ALAN: #REF!
Name ALEX: #REF!
Name ALEXA: #REF!
Name ALLAN: #REF!
Name ALMA: #REF!
Name AMA: #REF!
Name AMB: #REF!
Name AMBAR: #REF!
Name AMBRE: #REF!
Name ANA: #REF!
Name AP: #REF!
Name AX: #REF!
Name AXA: #REF!
Name AXE: #REF!
Name BA: #REF!
Name BASE: #REF!
Name BB: #REF!
Name BEN: #REF!
Name BENEF: #REF!
Name CASA: #REF!
Name CAT: #REF!
Name CATA: #REF!
Name CC: #REF!
Name color: #REF!
Name DA: #REF!
Name DAM: #REF!
Name DAMO: #REF!
Name DAT: #REF!
Name DATA: #REF!
Name DATAS: #REF!
Name DATIS: #REF!
Name DATOS: #REF!
Name DATOS1: #REF!
Name DD: #REF!
Name DEY: #REF!
Name DICE: #REF!
Name DUAL: #REF!
Name EDI: #REF!
Name FAM: #REF!
Name HERI: #REF!
Name HOLA: #REF!
Name HOLAS: #REF!
Name HOLIS: #REF!
Name INF: #REF!
Name LALO: #REF!
Name LECHE: #REF!
Name LECHERIA: #REF!
Name libreta: #REF!
Name MAMA: #REF!
Name MAR: #REF!
Name MARBE: #REF!
Name MARBELLA: #REF!
Name MARIO: #REF!
Name MARTE: #REF!
Name MARY: #REF!
Name MAY: #REF!

Sheet POR ALMACEN
B1: LECHE PARA EL BIENESTAR, S.A. DE C.V.
B2: GERENCIA ESTATAL OAXACA
B3: DEPARTAMENTO DE DISTRIBUCION Y TRANSPORTACION
B4: REQUERIMIENTO DE LECHE EN POLVO CORRESPONDIENTE AL MES DE MARZO DEL 2026
B5: LECHERIAS INCORPORADAS AL CONVENIO LECHE PARA EL BIENESTAR-ALIMENTACION PARA EL BIENESTAR
L6: PADRON DE BENEFICIARIOS. AL CIERRE DEL MES DE ENERO DEL 2026
B7: LECHERÍA | C7: TIENDA | E7: PADRÓN | G7: DOT. | H7: PROGRAMADO | I7: EXIST. | J7: EXISTENCIA | L7: PROGRAMADO | M7: EXIST.ESTIMADA | N7: % AJUSTE | P7: SOBRANTE | Q7: CAJAS | R7: GUIA DE DISTRIB.
B8: NÚM. | C8: No. | D8: L O C A L I D A D | E8: FAM. | F8: BENEF. | G8: MEN. | H8: ENERO | I8: EN | J8: CAJ. | K8: SOB. | L8: FEBRERO | M8: INICIO | N8: DOT. TEORICA | P8: ESTIM. P/ | Q8: SOLIC. X | R8: MARZO
G9: TEORICA | I9: ALMACEN | N9: % | O9: CAJAS | Q9: SUPERV.
B10: ::
C11: ALMACEN RURAL : CHALCATONGO
B12: LECHERIA | C12: num
B14: 120510 | C14: 11 | D14: SANTA CRUZ ITUNDUJIA | E14: 243 | F14: 351 | G14: =F14*0.666*24/72 -> 77.922 | H14: 55 | I14: 0 | J14: 0 | K14: 0 | L14: 55 | M14: 0 | O14: =ROUND((+G14*N14)/100,0) -> 0 | P14: =IF(M14>O14,+M14-O14,0) -> 0 | Q14: 60 | R14: =Q14 -> 60
B15: 377102 | C15: 18 | D15: HIDALGO | E15: 133 | F15: 175 | G15: =F15*0.666*24/72 -> 38.85 | H15: 25 | I15: 0 | J15: 0 | K15: 0 | L15: 20 | M15: 0 | O15: =ROUND((+G15*N15)/100,0) -> 0 | P15: =IF(M15>O15,+M15-O15,0) -> 0 | Q15: 23 | R15: =Q15 -> 23
B16: 377105 | C16: 33 | D16: INDEPENDENCIA | E16: 99 | F16: 126 | G16: =F16*0.666*24/72 -> 27.972 | H16: 10 | I16: 0 | J16: 0 | K16: 0 | L16: 10 | M16: 0 | O16: =ROUND((+G16*N16)/100,0) -> 0 | P16: =IF(M16>O16,+M16-O16,0) -> 0 | Q16: 10 | R16: =Q16 -> 10
B17: 377107 | C17: 26 | D17: GUERRERO | E17: 143 | F17: 176 | G17: =F17*0.666*24/72 -> 39.072 | H17: 20 | I17: 0 | J17: 0 | K17: 0 | L17: 20 | M17: 0 | O17: =ROUND((+G17*N17)/100,0) -> 0 | P17: =IF(M17>O17,+M17-O17,0) -> 0 | Q17: 20 | R17: =Q17 -> 20
B18: 377112 | C18: 31 | D18: BUENA VISTA DE JUAREZ | E18: 83 | F18: 124 | G18: =F18*0.666*24/72 -> 27.528 | H18: 10 | I18: 0 | J18: 0 | K18: 0 | L18: 9 | M18: 0 | O18: =ROUND((+G18*N18)/100,0) -> 0 | P18: =IF(M18>O18,+M18-O18,0) -> 0 | Q18: 9 | R18: =Q18 -> 9
B19: 382103 | C19: 42 | D19: SANTA CRUZ TACAHUA | E19: 62 | F19: 71 | G19: =F19*0.666*24/72 -> 15.762 | H19: 10 | I19: 0 | J19: 0 | K19: 0 | L19: 3 | M19: 0 | O19: =ROUND((+G19*N19)/100,0) -> 0 | P19: =IF(M19>O19,+M19-O19,0) -> 0 | Q19: 9 | R19: =Q19 -> 9
B20: 392101 | C20: 14 | D20: SANTA LUCIA MONTEVERDE | E20: 90 | F20: 101 | G20: =F20*0.666*24/72 -> 22.422 | H20: 12 | I20: 0 | J20: 0 | K20: 0 | L20: 12 | M20: 0 | O20: =ROUND((+G20*N20)/100,0) -> 0 | P20: =IF(M20>O20,+M20-O20,0) -> 0 | Q20: 12 | R20: =Q20 -> 12
B21: 392102 | C21: 24 | D21: YUTECOSO CUAUHTEMOC | E21: 62 | F21: 77 | G21: =F21*0.666*24/72 -> 17.094 | H21: 4 | I21: 0 | J21: 0 | K21: 0 | L21: 4 | M21: 0 | O21: =ROUND((+G21*N21)/100,0) -> 0 | P21: =IF(M21>O21,+M21-O21,0) -> 0 | Q21: 4 | R21: =Q21 -> 4
B22: 392110 | C22: 47 | D22: SANTA MARIA OCOTLAN | E22: 103 | F22: 139 | G22: =F22*0.666*24/72 -> 30.858 | H22: 10 | I22: 0 | J22: 0 | K22: 0 | L22: 10 | M22: 0 | O22: =ROUND((+G22*N22)/100,0) -> 0 | P22: =IF(M22>O22,+M22-O22,0) -> 0 | Q22: 10 | R22: =Q22 -> 10
B23: 450101 | C23: 66 | D23: SANTIAGO AMOLTEPEC | E23: 177 | F23: 323 | G23: =F23*0.666*24/72 -> 71.706 | H23: 35 | I23: 0 | J23: 0 | K23: 0 | L23: 0 | M23: 0 | O23: =ROUND((+G23*N23)/100,0) -> 0 | P23: =IF(M23>O23,+M23-O23,0) -> 0 | Q23: 0 | R23: =Q23 -> 0
B24: 500102 | C24: 27 | D24: SANTIAGO YOSONDUA | E24: 249 | F24: 404 | G24: =F24*0.666*24/72 -> 89.688 | H24: 40 | I24: 0 | J24: 0 | K24: 0 | L24: 40 | M24: 0 | O24: =ROUND((+G24*N24)/100,0) -> 0 | P24: =IF(M24>O24,+M24-O24,0) -> 0 | Q24: 4 | R24: =Q24 -> 4
B25: 500103 | C25: 25 | D25: YOLOTEPEC DE LA PAZ | E25: 104 | F25: 138 | G25: =F25*0.666*24/72 -> 30.636 | H25: 7 | I25: 0 | J25: 0 | K25: 0 | L25: 6 | M25: 0 | O25: =ROUND((+G25*N25)/100,0) -> 0 | P25: =IF(M25>O25,+M25-O25,0) -> 0 | Q25: 6 | R25: =Q25 -> 6
B26: 500104 | C26: 41 | D26: SANTA CATARINA CUANANA | E26: 134 | F26: 201 | G26: =F26*0.666*24/72 -> 44.622 | H26: 23 | I26: 0 | J26: 0 | K26: 0 | L26: 22 | M26: 0 | O26: =ROUND((+G26*N26)/100,0) -> 0 | P26: =IF(M26>O26,+M26-O26,0) -> 0 | Q26: 22 | R26: =Q26 -> 22
B28: T O T A L | D28: =COUNTA(B14:B26) -> 13 | E28: =SUM(E14:E26) -> 1682 | F28: =SUM(F14:F26) -> 2406 | G28: =SUM(G14:G26) -> 534.132 | H28: =SUM(H14:H26) -> 261 | I28: =SUM(I14:I26) -> 0 | J28: =SUM(J14:J26) -> 0 | K28: =SUM(K14:K26) -> 0 | L28: =SUM(L14:L26) -> 211 | ... R28: =SUM(R14:R26) -> 189
B29: OBSERVACIONES: DE LAS CAJAS DE LECHE QUE SE ENCUENTRAN EN EL ALMACEN ENVIAR: 39 CAJAS PARA EL P.V. 2050010200
Q30: TOTAL A RECIBIR EN ALMACEN: | R30: =R28+R29 -> 189
B33: ::
C34: ALMACEN RURAL : COIXTLAHUACA
B37: 18101 | C37: 4 | D37: CONCEPCION BUENA VISTA | E37: 70 | F37: 140 | G37: =F37*0.666*24/72 -> 31.08 | H37: 18 | I37: 0 | J37: 0 | K37: 0 | L37: 15 | M37: 0 | O37: =ROUND((+G37*N37)/100,0) -> 0 | P37: =IF(M37>O37,+M37-O37,0) -> 0 | Q37: 20 | R37: =Q37 -> 20
B38: 151101 | C38: 6 | D38: SAN FRANCISCO TEOPAN | E38: 36 | F38: 52 | G38: =F38*0.666*24/72 -> 11.544 | H38: 8 | I38: 0 | J38: 0 | K38: 0 | L38: 8 | M38: 0 | O38: =ROUND((+G38*N38)/100,0) -> 0 | P38: =IF(M38>O38,+M38-O38,0) -> 0 | Q38: 8 | R38: =Q38 -> 8
B39: 176102 | C39: 9 | D39: SN, JUAN BAUTISTA COIXTLAHUACA | E39: 203 | F39: 300 | G39: =F39*0.666*24/72 -> 66.6 | H39: 51 | I39: 0 | J39: 0 | K39: 0 | L39: 52 | M39: 0 | O39: =ROUND((+G39*N39)/100,0) -> 0 | P39: =IF(M39>O39,+M39-O39,0) -> 0 | Q39: 53 | R39: =Q39 -> 53
B40: 176103 | C40: 23 | D40: LA ESTANCIA COIXTLAHUACA | E40: 60 | F40: 95 | G40: =F40*0.666*24/72 -> 21.09 | H40: 22 | I40: 0 | J40: 0 | K40: 0 | L40: 21 | M40: 0 | O40: =ROUND((+G40*N40)/100,0) -> 0 | P40: =IF(M40>O40,+M40-O40,0) -> 0 | Q40: 14 | R40: =Q40 -> 14
B41: 270102 | C41: 17 | D41: SAN MIGUEL HUAUTLA | E41: 55 | F41: 72 | G41: =F41*0.666*24/72 -> 15.984 | H41: 7 | I41: 0 | J41: 0 | K41: 0 | L41: 12 | M41: 0 | O41: =ROUND((+G41*N41)/100,0) -> 0 | P41: =IF(M41>O41,+M41-O41,0) -> 0 | Q41: 5 | R41: =Q41 -> 5
B42: 321101 | C42: 15 | D42: SAN PEDRO NOPALA | E42: 67 | F42: 101 | G42: =F42*0.666*24/72 -> 22.422 | H42: 15 | I42: 0 | J42: 0 | K42: 0 | L42: 16 | M42: 0 | O42: =ROUND((+G42*N42)/100,0) -> 0 | P42: =IF(M42>O42,+M42-O42,0) -> 0 | Q42: 15 | R42: =Q42 -> 15
B43: 416101 | C43: 12 | D43: SANTA MARIA IXCATLAN | E43: 47 | F43: 60 | G43: =F43*0.666*24/72 -> 13.32 | H43: 13 | I43: 0 | J43: 0 | K43: 0 | L43: 13 | M43: 0 | O43: =ROUND((+G43*N43)/100,0) -> 0 | P43: =IF(M43>O43,+M43-O43,0) -> 0 | Q43: 11 | R43: =Q43 -> 11
B44: 451101 | C44: 16 | D44: SANTIAGO APOALA | E44: 40 | F44: 51 | G44: =F44*0.666*24/72 -> 11.322 | H44: 3 | I44: 0 | J44: 0 | K44: 0 | L44: 8 | M44: 0 | O44: =ROUND((+G44*N44)/100,0) -> 0 | P44: =IF(M44>O44,+M44-O44,0) -> 0 | Q44: 3 | R44: =Q44 -> 3
B45: 464101 | C45: 5 | D45: SANTIAGO IHUITLAN PLUMAS | E45: 94 | F45: 159 | G45: =F45*0.666*24/72 -> 35.298 | H45: 27 | I45: 0 | J45: 0 | K45: 0 | L45: 21 | M45: 0 | O45: =ROUND((+G45*N45)/100,0) -> 0 | P45: 0 | Q45: 21 | R45: =Q45 -> 21
B47: T O T A L | D47: =COUNTA(B37:B45) -> 9 | E47: =SUM(E37:E45) -> 672 | F47: =SUM(F37:F45) -> 1030 | G47: =SUM(G37:G45) -> 228.66 | H47: =SUM(H37:H45) -> 164 | I47: =SUM(I37:I45) -> 0 | J47: =SUM(J37:J45) -> 0 | K47: =SUM(K37:K45) -> 0 | L47: =SUM(L37:L45) -> 166 | ... R47: =SUM(R37:R45) -> 150
...

Sheet TOTAL
A1: LECHE PARA EL BIENESTAR, S.A. DE C.V.
A2: GERENCIA ESTATAL OAXACA
A3: DEPARTAMENTO DE DISTRIBUCIÓN Y TRANSPORTACIÓN
A4: =+'POR ALMACEN'!B4 -> REQUERIMIENTO DE LECHE EN POLVO CORRESPONDIENTE AL MES DE MARZO DEL 2026 | C4: REQUERIMIENTO DE LECHE EN POLVO CORRESPONDIENTE AL MES DE ENERO DEL 2022.
A5: LECHERIAS INCORPORADAS AL CONVENIO LECHE PARA EL BIENESTAR-ALIMENTACION PARA EL BIENJESTAR
A6: PRECIO PREFERENCIAL $4.50
A7: ALMACEN DICONSA | C7: NUMERO DE TIENDAS | D7: PADRÓN | F7: DOTACION MENSUAL TEOR. | G7: SOBRANTE EN ALMACEN RURAL | H7: * REQUERIMIENTO * | J7: TOTALES POR SUCURSALES RURALES
D8: FAM. | E8: BENEF. | H8: CAJAS | I8: CAJAS A ENVIAR A ALMC. RURAL
A11: SUCURSAL HUAJUAPAN | J11: =SUM(I13:I20) -> 1712
B13: CHALCATONGO | C13: =+'POR ALMACEN'!D28 -> 13 | D13: ='POR ALMACEN'!E28 -> 1682 | E13: ='POR ALMACEN'!F28 -> 2406 | F13: =+'POR ALMACEN'!G28 -> 534.132 | G13: =+'POR ALMACEN'!I28 -> 0 | H13: =+'POR ALMACEN'!Q28 -> 189 | I13: =H13-G13 -> 189
B14: COIXTLAHUACA | C14: =+'POR ALMACEN'!D47 -> 9 | D14: =+'POR ALMACEN'!E47 -> 672 | E14: =+'POR ALMACEN'!F47 -> 1030 | F14: =+'POR ALMACEN'!G47 -> 228.66 | G14: =+'POR ALMACEN'!I47 -> 0 | H14: =+'POR ALMACEN'!Q47 -> 150 | I14: =H14-G14 -> 150
B15: CONSTANCIA DEL ROSARIO | C15: =+'POR ALMACEN'!D61 -> 4 | D15: =+'POR ALMACEN'!E61 -> 419 | E15: =+'POR ALMACEN'!F61 -> 740 | F15: =+'POR ALMACEN'!G61 -> 164.28 | G15: =+'POR ALMACEN'!I61 -> 0 | H15: =+'POR ALMACEN'!Q61 -> 118 | I15: =H15-G15 -> 118
B16: HUAJOLOTITLAN | C16: =+'POR ALMACEN'!D78 -> 7 | D16: =+'POR ALMACEN'!E78 -> 749 | E16: =+'POR ALMACEN'!F78 -> 1207 | F16: =+'POR ALMACEN'!G78 -> 267.954 | G16: =+'POR ALMACEN'!I78 -> 0 | H16: =+'POR ALMACEN'!Q78 -> 187 | I16: =H16-G16 -> 187
B17: TACACHE DE MINA | C17: =+'POR ALMACEN'!D105 -> 17 | D17: =+'POR ALMACEN'!E105 -> 1478 | E17: =+'POR ALMACEN'!F105 -> 2366 | F17: =+'POR ALMACEN'!G105 -> 525.252 | G17: =+'POR ALMACEN'!I105 -> 0 | H17: =+'POR ALMACEN'!Q105 -> 281 | I17: =H17-G17 -> 281
B18: TLAXIACO | C18: =+'POR ALMACEN'!D128 -> 13 | D18: =+'POR ALMACEN'!E128 -> 1128 | E18: =+'POR ALMACEN'!F128 -> 1541 | F18: =+'POR ALMACEN'!G128 -> 342.102 | G18: =+'POR ALMACEN'!I128 -> 0 | H18: =+'POR ALMACEN'!Q128 -> 214 | I18: =H18-G18 -> 214
B19: TECOMAXTLAHUACA | C19: =+'POR ALMACEN'!D150 -> 12 | D19: =+'POR ALMACEN'!E150 -> 1068 | E19: =+'POR ALMACEN'!F150 -> 1813 | F19: =+'POR ALMACEN'!G150 -> 402.486 | G19: =+'POR ALMACEN'!I150 -> 0 | H19: =+'POR ALMACEN'!Q150 -> 241 | I19: =H19-G19 -> 241
B20: YANHUITLAN | C20: =+'POR ALMACEN'!D185 -> 24 | D20: =+'POR ALMACEN'!E185 -> 1832 | E20: =+'POR ALMACEN'!F185 -> 2827 | F20: =+'POR ALMACEN'!G185 -> 627.594 | G20: =+'POR ALMACEN'!I185 -> 0 | H20: =+'POR ALMACEN'!Q185 -> 332 | I20: =H20-G20 -> 332
A22: SUCURSAL ISTMO-COSTA | J22: =SUM(I24:I33) -> 1755
B24: MORRO MAZATAN | C24: =+'POR ALMACEN'!D196 -> 3 | D24: ='POR ALMACEN'!E196 -> 258 | E24: ='POR ALMACEN'!F196 -> 402 | F24: =+'POR ALMACEN'!G196 -> 89.244 | G24: =+'POR ALMACEN'!I196 -> 0 | H24: ='POR ALMACEN'!Q196 -> 72 | I24: =H24-G24 -> 72
B25: PALOMARES | C25: =+'POR ALMACEN'!D206 -> 2 | D25: ='POR ALMACEN'!E206 -> 185 | E25: ='POR ALMACEN'!F206 -> 322 | F25: =+'POR ALMACEN'!G203 -> 41.07 | G25: =+'POR ALMACEN'!I205 -> 0 | H25: =+'POR ALMACEN'!Q206 -> 10 | I25: =H25-G25 -> 10
B26: SANTIAGO LAOLLAGA | C26: =+'POR ALMACEN'!D222 -> 7 | D26: ='POR ALMACEN'!E222 -> 817 | E26: ='POR ALMACEN'!F222 -> 1245 | F26: ='POR ALMACEN'!G222 -> 276.39 | G26: =+'POR ALMACEN'!I206 -> 0 | H26: =+'POR ALMACEN'!Q222 -> 196 | I26: =H26-G26 -> 196
B27: SANTIAGO NILTEPEC | C27: =+'POR ALMACEN'!D232 -> 1 | D27: ='POR ALMACEN'!E232 -> 79 | E27: ='POR ALMACEN'!F232 -> 116 | F27: ='POR ALMACEN'!G232 -> 25.752 | G27: =+'POR ALMACEN'!I231 -> 0 | H27: =+'POR ALMACEN'!Q232 -> 22 | I27: =H27-G27 -> 22
B28: EL TOMATAL | C28: =+'POR ALMACEN'!D250 -> 9 | D28: ='POR ALMACEN'!E250 -> 639 | E28: ='POR ALMACEN'!F250 -> 1026 | F28: ='POR ALMACEN'!G250 -> 227.772 | G28: =+'POR ALMACEN'!I249 -> 0 | H28: =+'POR ALMACEN'!Q250 -> 165 | I28: =H28-G28 -> 165
B29: HUAXPALTEPEC | C29: =+'POR ALMACEN'!D276 -> 18 | D29: ='POR ALMACEN'!E276 -> 1567 | E29: ='POR ALMACEN'!F276 -> 2538 | F29: ='POR ALMACEN'!G276 -> 563.436 | G29: =+'POR ALMACEN'!I275 -> 0 | H29: =+'POR ALMACEN'!Q276 -> 369 | I29: =H29-G29 -> 369
B30: SANTA MARIA HUATULCO | C30: =+'POR ALMACEN'!D296 -> 11 | D30: ='POR ALMACEN'!E296 -> 1182 | E30: ='POR ALMACEN'!F296 -> 1843 | F30: ='POR ALMACEN'!G296 -> 409.146 | G30: =+'POR ALMACEN'!I295 -> 0 | H30: =+'POR ALMACEN'!Q296 -> 235 | I30: =H30-G30 -> 235
B31: LA REFORMA YAUTEPEC | C31: =+'POR ALMACEN'!D318 -> 12 | D31: ='POR ALMACEN'!E318 -> 650 | E31: ='POR ALMACEN'!F318 -> 1044 | F31: ='POR ALMACEN'!G318 -> 231.768 | G31: =+'POR ALMACEN'!I318 -> 0 | H31: =+'POR ALMACEN'!Q318 -> 148 | I31: =H31-G31 -> 148
B32: LOS IDEALES | C32: =+'POR ALMACEN'!D345 -> 16 | D32: ='POR ALMACEN'!E345 -> 2338 | E32: ='POR ALMACEN'!F345 -> 3906 | F32: ='POR ALMACEN'!G345 -> 867.132 | G32: =+'POR ALMACEN'!I344 -> 0 | H32: =+'POR ALMACEN'!Q345 -> 525 | I32: =H32-G32 -> 525
B33: PUEBLO NUEVO | C33: =+'POR ALMACEN'!D358 -> 2 | D33: ='POR ALMACEN'!E358 -> 77 | E33: ='POR ALMACEN'!F358 -> 140 | F33: ='POR ALMACEN'!G358 -> 31.08 | G33: =+'POR ALMACEN'!I357 -> 0 | H33: =+'POR ALMACEN'!Q358 -> 13 | I33: =H33-G33 -> 13
A35: SUCURSAL V. CENTRAL | J35: =SUM(I37:I48) -> 3325
B37: VALLES CENTRALES | C37: =+'POR ALMACEN'!D376 -> 9 | D37: ='POR ALMACEN'!E376 -> 669 | E37: ='POR ALMACEN'!F376 -> 1105 | F37: ='POR ALMACEN'!G376 -> 245.31 | G37: =+'POR ALMACEN'!I375 -> 0 | H37: =+'POR ALMACEN'!Q376 -> 144 | I37: =H37-G37 -> 144
B38: SAN ANDRES HIDALGO | C38: =+'POR ALMACEN'!D403 -> 18 | D38: ='POR ALMACEN'!E403 -> 3095 | E38: ='POR ALMACEN'!F403 -> 5230 | F38: ='POR ALMACEN'!G403 -> 1161.06 | G38: =+'POR ALMACEN'!I402 -> 0 | H38: =+'POR ALMACEN'!Q403 -> 749 | I38: =H38-G38 -> 749
B39: SAN JOSE DEL CHILAR | C39: =+'POR ALMACEN'!D428 -> 15 | D39: ='POR ALMACEN'!E428 -> 1036 | E39: ='POR ALMACEN'!F428 -> 1591 | F39: ='POR ALMACEN'!G428 -> 353.202 | G39: =+'POR ALMACEN'!I427 -> 0 | H39: =+'POR ALMACEN'!Q428 -> 193 | I39: =H39-G39 -> 193
B40: TEOTITLAN DE FLORES MAGON | C40: =+'POR ALMACEN'!D463 -> 26 | D40: ='POR ALMACEN'!E463 -> 1791 | E40: ='POR ALMACEN'!F463 -> 2604 | F40: ='POR ALMACEN'!G463 -> 578.088 | G40: =+'POR ALMACEN'!I462 -> 0 | H40: =+'POR ALMACEN'!Q463 -> 296 | I40: =H40-G40 -> 296
B41: AYUTLA MIXES | C41: =+'POR ALMACEN'!D497 -> 21 | D41: ='POR ALMACEN'!E497 -> 1763 | E41: ='POR ALMACEN'!F497 -> 2560 | F41: ='POR ALMACEN'!G497 -> 568.32 | G41: =+'POR ALMACEN'!I497 -> 0 | H41: =+'POR ALMACEN'!Q497 -> 200 | I41: =H41-G41 -> 200
B42: IXTLAN DE JUAREZ | C42: =+'POR ALMACEN'!D510 -> 2 | D42: ='POR ALMACEN'!E510 -> 134 | E42: ='POR ALMACEN'!F510 -> 178 | F42: ='POR ALMACEN'!G510 -> 39.516 | G42: =+'POR ALMACEN'!I510 -> 0 | H42: =+'POR ALMACEN'!Q510 -> 30 | I42: =H42-G42 -> 30
B43: MAGDALENA OCOTLAN | C43: =+'POR ALMACEN'!D533 -> 12 | D43: ='POR ALMACEN'!E533 -> 792 | E43: ='POR ALMACEN'!F533 -> 1306 | F43: ='POR ALMACEN'!G533 -> 289.932 | G43: =+'POR ALMACEN'!I533 -> 0 | H43: =+'POR ALMACEN'!Q533 -> 194 | I43: =H43-G43 -> 194
B44: SANTO TOMAS TAMAZULAPAN | C44: =+'POR ALMACEN'!D574 -> 31 | D44: ='POR ALMACEN'!E574 -> 2461 | E44: ='POR ALMACEN'!F574 -> 3592 | F44: ='POR ALMACEN'!G574 -> 797.424 | G44: =+'POR ALMACEN'!I574 -> 0 | H44: =+'POR ALMACEN'!Q574 -> 456 | I44: =H44-G44 -> 456
B45: SAN PEDRO JUCHATENGO | C45: =+'POR ALMACEN'!D598 -> 13 | D45: ='POR ALMACEN'!E598 -> 1778 | E45: ='POR ALMACEN'!F598 -> 2905 | F45: ='POR ALMACEN'!G598 -> 644.91 | G45: =+'POR ALMACEN'!I598 -> 0 | H45: =+'POR ALMACEN'!Q598 -> 412 | I45: =H45-G45 -> 412
B46: SANTA MARIA LACHIXIO | C46: =+'POR ALMACEN'!D631 -> 23 | D46: ='POR ALMACEN'!E631 -> 1846 | E46: ='POR ALMACEN'!F631 -> 3100 | F46: ='POR ALMACEN'!G631 -> 688.2 | G46: =+'POR ALMACEN'!I631 -> 0 | H46: =+'POR ALMACEN'!Q631 -> 536 | I46: =H46-G46 -> 536
B47: MATATLAN | C47: =+'POR ALMACEN'!D647 -> 7 | D47: ='POR ALMACEN'!E647 -> 671 | E47: ='POR ALMACEN'!F647 -> 959 | F47: ='POR ALMACEN'!G647 -> 212.898 | G47: =+'POR ALMACEN'!I647 -> 0 | H47: =+'POR ALMACEN'!Q647 -> 88 | I47: =H47-G47 -> 88
...
