Workbook
Name AA: #REF!
Name AAA: #REF!
Name ACTUAL: #REF!
Name AL: #REF!
Name ALAN: #REF!
Name ALEX: #REF!
Name ALEXA: #REF!
Name ALLAN: #REF!
Name ALMA: #REF!
Name AMA: #REF!
Name AMB: #REF!
Name AMBAR: #REF!
Name AMBRE: #REF!
Name ANA: #REF!
Name AP: #REF!
Name AX: #REF!
Name AXA: #REF!
Name AXE: #REF!
Name BA: #REF!
Name BASE: #REF!
Name BB: #REF!
Name BEN: #REF!
Name BENEF: #REF!
Name CASA: #REF!
Name CAT: #REF!
Name CATA: #REF!
Name CC: #REF!
Name color: #REF!
Name DA: #REF!
Name DAM: #REF!
Name DAMO: #REF!
Name DAT: #REF!
Name DATA: #REF!
Name DATAS: #REF!
Name DATIS: #REF!
Name DATOS: #REF!
Name DATOS: #REF!
Name DATOS1: #REF!
Name DD: #REF!
Name DEY: #REF!
Name DICE: #REF!
Name DUAL: #REF!
Name EDI: #REF!
Name FAM: #REF!
Name HERI: #REF!
Name HOLA: #REF!
Name HOLAS: #REF!
Name HOLIS: #REF!
Name INF: #REF!
Name LALO: #REF!
Name LECHE: #REF!
Name LECHERIA: #REF!
Name libreta: #REF!
Name MAMA: #REF!
Name MAR: #REF!
Name MARBE: #REF!
Name MARBELLA: #REF!
Name MARIO: #REF!
Name MARTE: #REF!
Name MARY: #REF!

Sheet POR ALMACEN
A1: LECHE PARA EL BIENESTAR, S.A. DE C.V.
A2: GERENCIA ESTATAL OAXACA
A3: DEPARTAMENTO DE DISTRIBUCION Y TRANSPORTACION
A4: REQUERIMIENTO DE LECHE EN POLVO CORRESPONDIENTE AL MES DE MARZO DEL 2026.
A5: LECHERIAS INCORPORADAS AL CONVENIO LECHE PARA EL BIENESTAR-ALIMENTACION PARA EL BIENESTAR 6.50 X LITRO
L6: PADRON DE BENEFICIARIOS. AL CIERRE DE ENERO 2026
A7: LECHERÍA | B7: TIENDA | D7: PADRÓN | F7: DOT. | G7: Envio | H7: EXIST. | I7: EXISTENCIA | K7: Envio Program. | L7: EXIST.ESTIMADA | M7: % AJUSTE | O7: SOBRANTE | P7: CAJAS | Q7: GUIA DIST.
A8: NÚM. | B8: No. | C8: L O C A L I D A D | D8: FAM. | E8: BENEF. | F8: MEN. | G8: ENERO | H8: EN | I8: CAJ. | J8: SOB. | K8: FEBRERO | L8: INICIO | M8: DOT. TEORICA | O8: ESTIM. P/ | P8: SOLIC. X | Q8: MARZO
F9: TEORICA | H9: ALMACEN | M9: % | N9: CAJAS | P9: SUPERV.
B11: ALMACEN RURAL : CHALCATONGO
A14: 88104 | B14: 23 | C14: SAN ANDRÉS CABECERA NUEVA | D14: 69 | E14: 107 | F14: =E14*0.666*24/72 -> 23.754 | G14: 10 | H14: 0 | I14: 0 | J14: 0 | K14: 8 | L14: 0 | N14: 0 | O14: =IF(L14>N14,+L14-N14,0) -> 0 | P14: 9 | Q14: =+P14 -> 9
A15: 120423 | B15: 15 | C15: CHALCATONGO DE HIDALGO | D15: 325 | E15: 448 | F15: =E15*0.666*24/72 -> 99.456 | G15: 50 | H15: 0 | I15: 0 | J15: 0 | K15: 55 | L15: 0 | N15: =ROUND((+F15*M15)/100,0) -> 0 | O15: =IF(L15>N15,+L15-N15,0) -> 0 | P15: 60 | Q15: =+P15 -> 60
A16: 133106 | B16: 105 | C16: SAN ESTEBAN ATATLAHUCA | D16: 209 | E16: 263 | F16: =E16*0.666*24/72 -> 58.386 | G16: 38 | H16: 0 | I16: 0 | J16: 0 | K16: 43 | L16: 0 | N16: =ROUND((+F16*M16)/100,0) -> 0 | O16: =IF(L16>N16,+L16-N16,0) -> 0 | P16: 43 | Q16: =+P16 -> 43
A17: 269103 | B17: 106 | C17: SAN MIGUEL EL GRANDE | D17: 76 | E17: 100 | F17: =E17*0.666*24/72 -> 22.2 | G17: 12 | H17: 0 | I17: 0 | J17: 0 | K17: 12 | L17: 0 | N17: 0 | O17: =IF(L17>N17,+L17-N17,0) -> 0 | P17: 12 | Q17: =+P17 -> 12
A18: 320101 | B18: 4 | C18: SAN PEDRO MOLINOS | D18: 53 | E18: 74 | F18: =E18*0.666*24/72 -> 16.428 | G18: 6 | H18: 0 | I18: 0 | J18: 0 | K18: 6 | L18: 0 | N18: 0 | O18: =IF(L18>N18,+L18-N18,0) -> 0 | P18: 6 | Q18: =+P18 -> 6
A19: 371102 | B19: 119 | C19: SANTA CATARINA TICUA | D19: 76 | E19: 96 | F19: =E19*0.666*24/72 -> 21.312 | G19: 10 | H19: 0 | I19: 0 | J19: 0 | K19: 10 | L19: 0 | N19: 0 | O19: =IF(L19>N19,+L19-N19,0) -> 0 | P19: 10 | Q19: =+P19 -> 10
A20: 510102 | B20: 10 | C20: SANTO DOMINGO IXCATLAN | D20: 56 | E20: 65 | F20: =E20*0.666*24/72 -> 14.43 | G20: 10 | H20: 0 | I20: 0 | J20: 0 | K20: 7 | L20: 0 | N20: 0 | O20: =IF(L20>N20,+L20-N20,0) -> 0 | P20: 7 | Q20: =+P20 -> 7
A22: T O T A L | C22: =COUNTA(A14:A20) -> 7 | D22: =SUM(D14:D20) -> 864 | E22: =SUM(E14:E20) -> 1153 | F22: =SUM(F14:F20) -> 255.966 | G22: =SUM(G14:G20) -> 136 | H22: =SUM(H14:H20) -> 0 | I22: =SUM(I14:I20) -> 0 | J22: =SUM(J14:J20) -> 0 | K22: =SUM(K14:K20) -> 141 | ... Q22: =SUM(Q14:Q20) -> 147
A23: OBSERVACIONES:
P24: TOTAL A RECIBIR EN ALMACEN: | Q24: =Q22 -> 147
B27: ALMACEN RURAL : COIXTLAHUACA
A30: 100144 | B30: 50 | C30: VILLA DE TAMAZULAPAN DEL PROGRESO | D30: 296 | E30: 462 | F30: =E30*0.666*24/72 -> 102.564 | G30: 58 | H30: 0 | I30: 0 | J30: 0 | K30: 0 | L30: 0 | N30: =ROUND((+F30*M30)/100,0) -> 0 | O30: =IF(L30>N30,+L30-N30,0) -> 0 | P30: 59 | Q30: =+P30 -> 59
A31: 120438 | B31: 65 | C31: TEPELMEME VILLA DE MORELOS | D31: 133 | E31: 196 | F31: =E31*0.666*24/72 -> 43.512 | G31: 0 | H31: 0 | I31: 0 | J31: 0 | K31: 20 | L31: 0 | N31: =ROUND((+F31*M31)/100,0) -> 0 | O31: =IF(L31>N31,+L31-N31,0) -> 0 | P31: 1 | Q31: =+P31 -> 1
A32: 283101 | B32: 66 | C32: SAN MIGUEL TEQUIXTEPEC | D32: 91 | E32: 126 | F32: =E32*0.666*24/72 -> 27.972 | G32: 20 | H32: 0 | I32: 0 | J32: 0 | K32: 14 | L32: 0 | N32: =ROUND((+F32*M32)/100,0) -> 0 | O32: =IF(L32>N32,+L32-N32,0) -> 0 | P32: 18 | Q32: =+P32 -> 18
A33: 422101 | B33: 23 | C33: SANTA MARIA NATIVITAS | D33: 59 | E33: 81 | F33: =E33*0.666*24/72 -> 17.982 | G33: 15 | H33: 0 | I33: 0 | J33: 0 | K33: 15 | L33: 0 | N33: =ROUND((+F33*M33)/100,0) -> 0 | O33: =IF(L33>N33,+L33-N33,0) -> 0 | P33: 16 | Q33: =+P33 -> 16
A34: 552101 | B34: 27 | C34: TLACOTEPEC PLUMAS | D34: 54 | E34: 82 | F34: =E34*0.666*24/72 -> 18.204 | G34: 4 | H34: 0 | I34: 0 | J34: 0 | K34: 3 | L34: 0 | N34: =ROUND((+F34*M34)/100,0) -> 0 | O34: =IF(L34>N34,+L34-N34,0) -> 0 | P34: 4 | Q34: =+P34 -> 4
A35: 556101 | B35: 10 | C35: LA TRINIDAD VISTA HERMOSA | D35: 69 | E35: 107 | F35: =E35*0.666*24/72 -> 23.754 | G35: 6 | H35: 0 | I35: 0 | J35: 0 | K35: 7 | L35: 0 | N35: =ROUND((+F35*M35)/100,0) -> 0 | O35: =IF(L35>N35,+L35-N35,0) -> 0 | P35: 8 | Q35: =+P35 -> 8
A37: T O T A L | C37: =COUNTA(A30:A35) -> 6 | D37: =SUM(D30:D35) -> 702 | E37: =SUM(E30:E35) -> 1054 | F37: =SUM(F30:F35) -> 233.988 | G37: =SUM(G30:G35) -> 103 | H37: =SUM(H30:H35) -> 0 | I37: =SUM(I30:I35) -> 0 | J37: =SUM(J30:J35) -> 0 | K37: =SUM(K30:K35) -> 59 | ... Q37: =SUM(Q30:Q35) -> 106
A38: OBSERVACIONES: DE LAS CAJAS DE LECHE QUE SE ENCUENTRAN EN EL ALMACEN ENVIAR: 24 CAJAS PARA EL P.V. 2012043800
P39: TOTAL A RECIBIR EN ALMACEN: | Q39: =Q37 -> 106
B41: ALMACEN RURAL : CONSTANCIA DEL ROSARIO
A44: 73101 | B44: 46 | C44: SANTIAGO AMATE COLORADO | D44: 48 | E44: 82 | F44: =E44*0.666*24/72 -> 18.204 | G44: 12 | H44: 0 | I44: 0 | J44: 0 | K44: 10 | L44: 0 | N44: =ROUND((+F44*M44)/100,0) -> 0 | O44: =IF(L44>N44,+L44-N44,0) -> 0 | P44: 14 | Q44: =+P44 -> 14
A45: 73113 | B45: 13 | C45: SAN PEDRO SINIYUVI | D45: 65 | E45: 80 | F45: =E45*0.666*24/72 -> 17.76 | G45: 11 | H45: 0 | I45: 0 | J45: 0 | K45: 9 | L45: 0 | N45: =ROUND((+F45*M45)/100,0) -> 0 | O45: =IF(L45>N45,+L45-N45,0) -> 0 | P45: 12 | Q45: =+P45 -> 12
A46: 73114 | B46: 9 | C46: SAN ANDRES CHICAHUAXTLA | D46: 67 | E46: 80 | F46: =E46*0.666*24/72 -> 17.76 | G46: 2 | H46: 0 | I46: 0 | J46: 0 | K46: 7 | L46: 0 | N46: =ROUND((+F46*M46)/100,0) -> 0 | O46: =IF(L46>N46,+L46-N46,0) -> 0 | P46: 8 | Q46: =+P46 -> 8
A47: 73115 | B47: 31 | C47: ASUNCION ATOYAQUILLO | D47: 94 | E47: 110 | F47: =E47*0.666*24/72 -> 24.42 | G47: 0 | H47: 0 | I47: 0 | J47: 0 | K47: 0 | L47: 0 | N47: =ROUND((+F47*M47)/100,0) -> 0 | O47: =IF(L47>N47,+L47-N47,0) -> 0 | P47: 25 | Q47: =+P47 -> 25
A48: 76101 | B48: 33 | C48: LA REFORMA | D48: 65 | E48: 105 | F48: =E48*0.666*24/72 -> 23.31 | G48: 23 | H48: 0 | I48: 0 | J48: 0 | K48: 0 | L48: 0 | N48: =ROUND((+F48*M48)/100,0) -> 0 | O48: =IF(L48>N48,+L48-N48,0) -> 0 | P48: 22 | Q48: =+P48 -> 22
A49: 76102 | B49: 42 | C49: ESTANZUELA GRANDE | D49: 61 | E49: 96 | F49: =E49*0.666*24/72 -> 21.312 | G49: 19 | H49: 0 | I49: 0 | J49: 0 | K49: 17 | L49: 0 | N49: =ROUND((+F49*M49)/100,0) -> 0 | O49: =IF(L49>N49,+L49-N49,0) -> 0 | P49: 18 | Q49: =+P49 -> 18
A50: 120347 | B50: 79 | C50: PUTLA VILLA DE GUERRERO | D50: 461 | E50: 683 | F50: =E50*0.666*24/72 -> 151.626 | G50: 88 | H50: 0 | I50: 0 | J50: 0 | K50: 88 | L50: 0 | N50: =ROUND((+F50*M50)/100,0) -> 0 | O50: =IF(L50>N50,+L50-N50,0) -> 0 | P50: 94 | Q50: =+P50 -> 94
A51: 120427 | B51: 93 | C51: GUADALUPE NUEVO TENOCHTITLAN | D51: 60 | E51: 85 | F51: =E51*0.666*24/72 -> 18.87 | G51: 14 | H51: 0 | I51: 0 | J51: 0 | K51: 0 | L51: 0 | N51: =ROUND((+F51*M51)/100,0) -> 0 | O51: =IF(L51>N51,+L51-N51,0) -> 0 | P51: 14 | Q51: =+P51 -> 14
A52: 120535 | B52: 24 | C52: SANTA MARIA ZACATEPEC | D52: 294 | E52: 475 | F52: =E52*0.666*24/72 -> 105.45 | G52: 70 | H52: 0 | I52: 0 | J52: 0 | K52: 79 | L52: 0 | N52: =ROUND((+F52*M52)/100,0) -> 0 | O52: =IF(L52>N52,+L52-N52,0) -> 0 | P52: 80 | Q52: =+P52 -> 80
...

Sheet TOTAL
A1: LECHE PARA EL BIENESTAR, S.A. DE C.V.
A2: GERENCIA ESTATAL OAXACA
A3: DEPARTAMENTO DE DISTRIBUCIÓN Y TRANSPORTACIÓN
A4: =+'POR ALMACEN'!A4 -> REQUERIMIENTO DE LECHE EN POLVO CORRESPONDIENTE AL MES DE MARZO DEL 2026.
A5: LECHERIAS INCORPORADAS AL CONVENIO LECHE PARA EL BIENESTAR-ALIMENTACION PARA EL BIENESTAR Precio $6.50 Lt. COD:1360
A7: ALMACEN DICONSA | C7: NUMERO DE TIENDAS | D7: PADRÓN | F7: DOTACION MENSUAL TEOR. | G7: SOBRANTE EN ALMACEN RURAL | H7: * REQUERIMIENTO * | J7: TOTALES POR SUCURSALES RURALES
D8: FAM. | E8: BENEF. | H8: CAJAS | I8: CAJAS A ENVIAR A ALMC. RURAL
A11: SUCURSAL HUAJUAPAN | J11: =SUM(I13:I20) -> 1812
B13: CHALCATONGO | C13: =+'POR ALMACEN'!C22 -> 7 | D13: =+'POR ALMACEN'!D22 -> 864 | E13: =+'POR ALMACEN'!E22 -> 1153 | F13: =+'POR ALMACEN'!F22 -> 255.966 | G13: 0 | H13: =+'POR ALMACEN'!P22 -> 147 | I13: =H13-G13 -> 147
B14: COIXTLAHUACA | C14: =+'POR ALMACEN'!C37 -> 6 | D14: =+'POR ALMACEN'!D37 -> 702 | E14: =+'POR ALMACEN'!E37 -> 1054 | F14: =+'POR ALMACEN'!F37 -> 233.988 | G14: 0 | H14: =+'POR ALMACEN'!P37 -> 106 | I14: =H14-G14 -> 106
B15: CONSTANCIA DEL ROSARIO | C15: =+'POR ALMACEN'!C62 -> 17 | D15: =+'POR ALMACEN'!D62 -> 1736 | E15: =+'POR ALMACEN'!E62 -> 2527 | F15: =+'POR ALMACEN'!F62 -> 560.994 | G15: 0 | H15: =+'POR ALMACEN'!P62 -> 392 | I15: =H15-G15 -> 392
B16: HUAJOLOTITLAN | C16: =+'POR ALMACEN'!C85 -> 15 | D16: =+'POR ALMACEN'!D85 -> 1427 | E16: =+'POR ALMACEN'!E85 -> 2083 | F16: =+'POR ALMACEN'!F85 -> 462.426 | G16: 0 | H16: =+'POR ALMACEN'!P85 -> 328 | I16: =H16-G16 -> 328
B17: TACACHE DE MINA | C17: =+'POR ALMACEN'!C96 -> 3 | D17: =+'POR ALMACEN'!D96 -> 285 | E17: =+'POR ALMACEN'!E96 -> 417 | F17: =+'POR ALMACEN'!F96 -> 150 | G17: 0 | H17: =+'POR ALMACEN'!P96 -> 52 | I17: =H17-G17 -> 52
B18: TLAXIACO | C18: =+'POR ALMACEN'!C122 -> 18 | D18: =+'POR ALMACEN'!D122 -> 2120 | E18: =+'POR ALMACEN'!E122 -> 2986 | F18: =+'POR ALMACEN'!F122 -> 662.892 | G18: 0 | H18: =+'POR ALMACEN'!P122 -> 393 | I18: =H18-G18 -> 393
B19: TECOMAXTLAHUACA | C19: =+'POR ALMACEN'!C133 -> 3 | D19: =+'POR ALMACEN'!D133 -> 615 | E19: =+'POR ALMACEN'!E133 -> 1079 | F19: =+'POR ALMACEN'!F133 -> 239.538 | G19: 0 | H19: =+'POR ALMACEN'!P133 -> 162 | I19: =H19-G19 -> 162
B20: YANHUITLAN | C20: =+'POR ALMACEN'!C153 -> 12 | D20: =+'POR ALMACEN'!D153 -> 1083 | E20: =+'POR ALMACEN'!E153 -> 1512 | F20: =+'POR ALMACEN'!F153 -> 335.664 | G20: 0 | H20: =+'POR ALMACEN'!P153 -> 232 | I20: =H20-G20 -> 232
A22: SUCURSAL ISTMO-COSTA | J22: =SUM(I24:I33) -> 2821
B24: MORRO MAZATAN | C24: =+'POR ALMACEN'!C170 -> 9 | D24: =+'POR ALMACEN'!D170 -> 1485 | E24: =+'POR ALMACEN'!E170 -> 2139 | F24: =+'POR ALMACEN'!F170 -> 474.858 | G24: 0 | H24: =+'POR ALMACEN'!P170 -> 424 | I24: =H24-G24 -> 424
B25: PALOMARES | C25: =+'POR ALMACEN'!C191 -> 11 | D25: =+'POR ALMACEN'!D191 -> 846 | E25: =+'POR ALMACEN'!E191 -> 1268 | F25: =+'POR ALMACEN'!F191 -> 281.496 | G25: 0 | H25: =+'POR ALMACEN'!P191 -> 94 | I25: =H25-G25 -> 94
B26: SANTIAGO LAOLLAGA | C26: =+'POR ALMACEN'!C206 -> 7 | D26: =+'POR ALMACEN'!D206 -> 677 | E26: =+'POR ALMACEN'!E206 -> 1019 | F26: =+'POR ALMACEN'!F206 -> 226.218 | G26: 0 | H26: =+'POR ALMACEN'!P206 -> 122 | I26: =H26-G26 -> 122
B27: SANTIAGO NILTEPEC | C27: =+'POR ALMACEN'!C236 -> 22 | D27: =+'POR ALMACEN'!D236 -> 1718 | E27: =+'POR ALMACEN'!E236 -> 2563 | F27: =+'POR ALMACEN'!F236 -> 568.986 | G27: 0 | H27: =+'POR ALMACEN'!P236 -> 333 | I27: =H27-G27 -> 333
B28: EL TOMATAL | C28: =+'POR ALMACEN'!C261 -> 15 | D28: =+'POR ALMACEN'!D261 -> 2496 | E28: =+'POR ALMACEN'!E261 -> 3906 | F28: =+'POR ALMACEN'!F261 -> 867.132 | G28: 0 | H28: =+'POR ALMACEN'!P261 -> 587 | I28: =H28-G28 -> 587
B29: HUAXPALTEPEC | C29: =+'POR ALMACEN'!C301 -> 29 | D29: =+'POR ALMACEN'!D301 -> 3474 | E29: =+'POR ALMACEN'!E301 -> 5302 | F29: =+'POR ALMACEN'!F301 -> 1177.044 | G29: 0 | H29: =+'POR ALMACEN'!P301 -> 728 | I29: =H29-G29 -> 728
B30: SANTA MARIA HUATULCO | C30: =+'POR ALMACEN'!C321 -> 11 | D30: =+'POR ALMACEN'!D321 -> 1165 | E30: =+'POR ALMACEN'!E321 -> 1664 | F30: =+'POR ALMACEN'!F321 -> 369.408 | G30: 0 | H30: =+'POR ALMACEN'!P321 -> 162 | I30: =H30-G30 -> 162
B31: LA REFORMA YAUTEPEC | C31: =+'POR ALMACEN'!C337 -> 7 | D31: =+'POR ALMACEN'!D337 -> 600 | E31: =+'POR ALMACEN'!E337 -> 858 | F31: =+'POR ALMACEN'!F337 -> 190.476 | G31: 0 | H31: =+'POR ALMACEN'!P337 -> 125 | I31: =H31-G31 -> 125
B32: LOS IDEALES | C32: =+'POR ALMACEN'!C345 -> 0 | D32: =+'POR ALMACEN'!D345 -> 0 | E32: =+'POR ALMACEN'!E345 -> 0 | F32: =+'POR ALMACEN'!F345 -> 0 | G32: 0 | H32: =+'POR ALMACEN'!P345 -> 0 | I32: =H32-G32 -> 0
B33: PUEBLO NUEVO | C33: =+'POR ALMACEN'!C364 -> 11 | D33: =+'POR ALMACEN'!D364 -> 934 | E33: =+'POR ALMACEN'!E364 -> 1512 | F33: =+'POR ALMACEN'!F364 -> 335.664 | G33: 0 | H33: =+'POR ALMACEN'!P364 -> 246 | I33: =H33-G33 -> 246
A35: SUCURSAL V. CENTRAL | J35: =SUM(I37:I48) -> 1149
B37: VALLES CENTRALES | C37: =+'POR ALMACEN'!C379 -> 5 | D37: =+'POR ALMACEN'!D379 -> 367 | E37: =+'POR ALMACEN'!E379 -> 523 | F37: =+'POR ALMACEN'!F379 -> 116.106 | G37: 0 | H37: =+'POR ALMACEN'!P379 -> 37 | I37: =H37-G37 -> 37
B38: SAN ANDRES HIDALGO | C38: =+'POR ALMACEN'!C391 -> 4 | D38: =+'POR ALMACEN'!D391 -> 310 | E38: =+'POR ALMACEN'!E391 -> 418 | F38: =+'POR ALMACEN'!F391 -> 92.796 | G38: 0 | H38: =+'POR ALMACEN'!P391 -> 58 | I38: =H38-G38 -> 58
B39: SAN JOSE DEL CHILAR | C39: =+'POR ALMACEN'!C405 -> 4 | D39: =+'POR ALMACEN'!D405 -> 423 | E39: =+'POR ALMACEN'!E405 -> 704 | F39: =+'POR ALMACEN'!F405 -> 156.288 | G39: 0 | H39: =+'POR ALMACEN'!P405 -> 103 | I39: =H39-G39 -> 103
B40: TEOTITLAN DE FLORES MAGON | C40: =+'POR ALMACEN'!C419 -> 6 | D40: =+'POR ALMACEN'!D419 -> 754 | E40: =+'POR ALMACEN'!E419 -> 1037 | F40: =+'POR ALMACEN'!F419 -> 230.214 | G40: 0 | H40: =+'POR ALMACEN'!P419 -> 160 | I40: =H40-G40 -> 160
B41: AYUTLA MIXES | C41: =+'POR ALMACEN'!C432 -> 5 | D41: =+'POR ALMACEN'!D432 -> 478 | E41: =+'POR ALMACEN'!E432 -> 643 | F41: =+'POR ALMACEN'!F432 -> 126.096 | G41: 0 | H41: =+'POR ALMACEN'!P432 -> 107 | I41: =H41-G41 -> 107
B42: IXTLAN DE JUAREZ | C42: =+'POR ALMACEN'!C451 -> 11 | D42: =+'POR ALMACEN'!D451 -> 676 | E42: =+'POR ALMACEN'!E451 -> 922 | F42: =+'POR ALMACEN'!F451 -> 204.684 | G42: 0 | H42: =+'POR ALMACEN'!P451 -> 166 | I42: =H42-G42 -> 166
B43: MAGDALENA OCOTLAN | C43: =+'POR ALMACEN'!C464 -> 5 | D43: =+'POR ALMACEN'!D464 -> 202 | E43: =+'POR ALMACEN'!E464 -> 261 | F43: ='POR ALMACEN'!F464 -> 57.942 | G43: 0 | H43: =+'POR ALMACEN'!P464 -> 40 | I43: =H43-G43 -> 40
B44: SANTO TOMAS TAMAZULAPAN | C44: =+'POR ALMACEN'!C483 -> 11 | D44: =+'POR ALMACEN'!D483 -> 1253 | E44: =+'POR ALMACEN'!E483 -> 1839 | F44: =+'POR ALMACEN'!F483 -> 408.258 | G44: 0 | H44: =+'POR ALMACEN'!P483 -> 157 | I44: =H44-G44 -> 157
B45: SAN PEDRO JUCHATENGO | C45: =+'POR ALMACEN'!C499 -> 7 | D45: =+'POR ALMACEN'!D499 -> 969 | E45: =+'POR ALMACEN'!E499 -> 1543 | F45: =+'POR ALMACEN'!F499 -> 342.546 | G45: 0 | H45: =+'POR ALMACEN'!P499 -> 240 | I45: =H45-G45 -> 240
B46: SANTA MARIA LACHIXIO | C46: =+'POR ALMACEN'!C511 -> 3 | D46: =+'POR ALMACEN'!D511 -> 142 | E46: =+'POR ALMACEN'!E511 -> 206 | F46: =+'POR ALMACEN'!F511 -> 45.732 | G46: 0 | H46: =+'POR ALMACEN'!P511 -> 34 | I46: =H46-G46 -> 34
B47: MATATLAN | C47: =+'POR ALMACEN'!C521 -> 2 | D47: =+'POR ALMACEN'!D521 -> 148 | E47: =+'POR ALMACEN'!E521 -> 211 | F47: =+'POR ALMACEN'!F521 -> 46.842 | G47: 0 | H47: =+'POR ALMACEN'!P521 -> 20 | I47: =H47-G47 -> 20
B48: CUAJIMOLOYAS | C48: =+'POR ALMACEN'!C533 -> 4 | D48: =+'POR ALMACEN'!D533 -> 209 | E48: =+'POR ALMACEN'!E533 -> 261 | F48: =+'POR ALMACEN'!F533 -> 57.942 | G48: 0 | H48: =+'POR ALMACEN'!P533 -> 27 | I48: =H48-G48 -> 27
...
