Workbook
Name AA: #REF!
Name AAA: #REF!
Name ACTUAL: #REF!
Name AL: #REF!
Name ALAN: #REF!
Name ALEX: #REF!
Name ALEXA: #REF!
Name ALLAN: #REF!
Name ALMA: #REF!
Name AMA: #REF!
Name AMB: #REF!
Name AMBAR: #REF!
Name AMBRE: #REF!
Name ANA: #REF!
Name AP: #REF!
Name AX: #REF!
Name AXA: #REF!
Name AXE: #REF!
Name BA: #REF!
Name BASE: #REF!
Name BB: #REF!
Name BEN: #REF!
Name BENEF: #REF!
Name CASA: #REF!
Name CAT: #REF!
Name CATA: #REF!
Name CC: #REF!
Name color: #REF!
Name DA: #REF!
Name DAM: #REF!
Name DAMO: #REF!
Name DAT: #REF!
Name DATA: #REF!
Name DATAS: #REF!
Name DATIS: #REF!
Name DATOS: #REF!
Name DATOS: #REF!
Name DATOS1: #REF!
Name DD: #REF!
Name DEY: #REF!
Name DEYSI: #REF!
Name DICE: #REF!
Name DUAL: #REF!
Name EDI: #REF!
Name FAM: #REF!
Name HERI: #REF!
Name HOLA: #REF!
Name HOLAS: #REF!
Name HOLIS: #REF!
Name INF: #REF!
Name LALO: #REF!
Name LECHE: #REF!
Name LECHERIA: #REF!
Name libreta: #REF!
Name MAMA: #REF!
Name MAR: #REF!
Name MARBE: #REF!
Name MARBELLA: #REF!
Name MARIO: #REF!
Name MARTE: #REF!

Sheet catabril26
A1: AMB | B1: TIPO | C1: PRESE | D1: ZONA | E1: RUTA | F1: PRECIO | G1: PTO_VTA | H1: LECHERIA | I1: FAMILIAS | J1: MENORES | K1: ADULTOS | L1: BENEFICIARIOS | M1: LEC_AGEB_LOC_MUN_NUMERO | N1: MUN | O1: LEC_AGEB_LOC_NUMERO | P1: LOC | Q1: ' | R1: AMBITO | S1: '' | T1: NV | U1: ' | V1: NVM | W1: ' | X1: SUBSTR(LEC_CALLE_NUMERO,1,55) | Y1: ' | Z1: SUBSTR(LEC_COLONIA,1,42) | AA1: ' | AB1: SUBSTR(LEC_REFERENCIA_UBICACION,1,36 | AC1: ' | AD1: CP | AE1: '' | AF1: OTROP | AG1: '' | AH1: SUBSTR(TO_ | AI1: PRESE | AJ1: '' | AK1: PRESEN | AL1: '' | AM1: TPL_NUMERO | AN1: SUBSTR(TPL_DESCRIPCI | AO1: '' | AP1: REF_NUMERO | AQ1: SUBSTR(REF_DESCRI | AR1: PMT_NUMERO | AS1: SUBSTR(PMT_DESCRIPCIONL,1,60) | AT1: LEC_CONC_NUMERO | AU1: CONC_DESCRIPCIONL | AV1: TO_CH | AW1: TO_CH | AX1: LEC_COORDENADA_Y | AY1: LEC_COORDENADA_X
A2: R | B2: TD | C2: P | D2: 5 | E2: 1 | F2: 6.5 | G2: 2000210200 | H2: 2102 | I2: 111 | J2: 64 | K2: 104 | L2: =J2+K2 -> 168 | M2: 2 | N2: ACATLÁN DE PÉREZ FIGUEROA | O2: 19 | P2: JOLIETTE | R2: RURAL | T2: 2 | V2: ALTA | X2: DIAZ MIRON S/N | Z2: CENTRO | AB2: FRENTE A LA IGLESIA CATOLICA. | AD2: 68420 | AF2: EN OPERACION | AH2: 34690 | AI2: POLVO | AK2: CON VENTA DE BASICOS | AM2: 6 | AN2: TIENDA | AP2: 3 | AQ2: DICONSA | AR2: 3094 | AS2: FLORES SANTIAGO HECTOR DANIEL | AT2: 1 | AU2: NOMBRE CONCESIONARIO | AV2: 0.33333333 | AW2: 0.5625
A3: R | B3: TD | C3: P | D3: 3 | E3: 4 | F3: 6.5 | G3: 2000510100 | H3: 5101 | I3: 101 | J3: 71 | K3: 112 | L3: =J3+K3 -> 183 | M3: 5 | N3: ASUNCIÓN IXTALTEPEC | O3: 15 | P3: SANTIAGO IXTALTEPEC | R3: RURAL | T3: 3 | V3: MEDIA | X3: BENITO JUAREZ ESQ 10 DE ABRIL | Z3: CENTRO | AB3: FRENTE AL AUDITORIO MUNICIPAL | AD3: 70140 | AF3: EN OPERACION | AH3: 37455 | AI3: POLVO | AK3: CON VENTA DE BASICOS | AM3: 6 | AN3: TIENDA | AP3: 3 | AQ3: DICONSA | AR3: 3108 | AS3: MIGUEL ANGEL MARTINEZ PURA | AT3: 1 | AU3: NOMBRE CONCESIONARIO | AV3: 0.375 | AW3: 0.58333333
A4: R | B4: TD | C4: P | D4: 3 | E4: 4 | F4: 6.5 | G4: 2000510200 | H4: 5102 | I4: 82 | J4: 80 | K4: 50 | L4: =J4+K4 -> 130 | M4: 5 | N4: ASUNCIÓN IXTALTEPEC | O4: 7 | P4: LAZARO CARDENAS | R4: RURAL | T4: 2 | V4: ALTA | X4: NIÑO ARTILLERO S/N | Z4: LAZARO CARDENAS | AB4: AV. IGNACIO ZARAGOZA Y AV, BENITO JU | AD4: 70145 | AF4: EN OPERACION | AH4: 45043 | AI4: POLVO | AK4: CON VENTA DE BASICOS | AM4: 6 | AN4: TIENDA | AP4: 3 | AQ4: DICONSA | AR4: 3108 | AS4: MIGUEL ANGEL MARTINEZ PURA | AT4: 1 | AU4: NOMBRE CONCESIONARIO | AV4: 0.375 | AW4: 0.58333333
A5: R | B5: TD | C5: P | D5: 3 | E5: 3 | F5: 6.5 | G5: 2000510300 | H5: 5103 | I5: 339 | J5: 147 | K5: 328 | L5: =J5+K5 -> 475 | M5: 5 | N5: ASUNCIÓN IXTALTEPEC | O5: 1 | P5: ASUNCION IXTALTEPEC | R5: RURAL | T5: 3 | V5: MEDIA | X5: CANAL 33 S/N | Z5: ASUNCIÓN IXTALTEPEC (TERCERA SECCIÓN) | AB5: LA LECHERÍA SE UBICARÁ EN LA TIENDA | AD5: 70140 | AF5: EN OPERACION | AH5: 45624 | AI5: POLVO | AK5: CON VENTA DE BASICOS | AM5: 6 | AN5: TIENDA | AP5: 3 | AQ5: DICONSA | AR5: 3148 | AS5: CARPIO RITO JOSE LEONARDO | AT5: 208781 | AU5: SANCHEZ HERNANDEZ LUCILA | AV5: 0.375 | AW5: 0.58333333
A6: R | B6: TD | C6: P | D6: 5 | E6: 2 | F6: 6.5 | G6: 2000910200 | H6: 9102 | I6: 91 | J6: 107 | K6: 68 | L6: =J6+K6 -> 175 | M6: 9 | N6: AYOTZINTEPEC | O6: 1 | P6: AYOTZINTEPEC | R6: RURAL | T6: 2 | V6: ALTA | X6: 5 DE MAYO S/N | Z6: AYOTZINTEPEC | AB6: CALLE MORELOS Y CALLE JOSEFA ORTIZ D | AD6: 68435 | AF6: EN OPERACION | AH6: 44799 | AI6: POLVO | AK6: CON VENTA DE BASICOS | AM6: 6 | AN6: TIENDA | AP6: 3 | AQ6: DICONSA | AR6: 3059 | AS6: PEREZ DOMINGUEZ SILVIA | AT6: 1 | AU6: NOMBRE CONCESIONARIO | AV6: 0.375 | AW6: 0.58333333
A7: R | B7: TD | C7: P | D7: 5 | E7: 2 | F7: 6.5 | G7: 2000910300 | H7: 9103 | I7: 51 | J7: 29 | K7: 57 | L7: =J7+K7 -> 86 | M7: 9 | N7: AYOTZINTEPEC | O7: 13 | P7: SAN JOSE MANO MARQUES | R7: RURAL | T7: 2 | V7: ALTA | X7: FRANCISCO VILLA S/N | Z7: SAN JOSÉ MANO MARQUÉS | AB7: CERCA DEL TANQUE ELEVADO | AD7: 68438 | AF7: EN OPERACION | AH7: 45863 | AI7: POLVO | AK7: CON VENTA DE BASICOS | AM7: 6 | AN7: TIENDA | AP7: 3 | AQ7: DICONSA | AR7: 3059 | AS7: PEREZ DOMINGUEZ SILVIA | AT7: 208653 | AU7: PERALTA REYES RAMIRO | AV7: 0.375 | AW7: 0.58333333
A8: R | B8: TD | C8: P | D8: 3 | E8: 4 | F8: 6.5 | G8: 2001010400 | H8: 10104 | I8: 36 | J8: 16 | K8: 45 | L8: =J8+K8 -> 61 | M8: 10 | N8: EL BARRIO DE LA SOLEDAD | O8: 13 | P8: RIO GRANDE | R8: RURAL | T8: 4 | V8: BAJA | X8: BENITO JUÁREZ S/N | Z8: RIO GRANDE | AB8: CALLE PRIMERO DE MAYO Y CALLE BENITO | AD8: 70382 | AF8: EN OPERACION | AH8: 44825 | AI8: POLVO | AK8: CON VENTA DE BASICOS | AM8: 6 | AN8: TIENDA | AP8: 3 | AQ8: DICONSA | AR8: 3108 | AS8: MIGUEL ANGEL MARTINEZ PURA | AT8: 1 | AU8: NOMBRE CONCESIONARIO | AV8: 0.375 | AW8: 0.58333333
A9: R | B9: TD | C9: P | D9: 3 | E9: 4 | F9: 6.5 | G9: 2001010500 | H9: 10105 | I9: 87 | J9: 47 | K9: 84 | L9: =J9+K9 -> 131 | M9: 10 | N9: EL BARRIO DE LA SOLEDAD | O9: 3 | P9: ALMOLOYA DE GUTIERREZ | R9: RURAL | T9: 2 | V9: ALTA | X9: REVOLUCIÓN S/N | Z9: ALMOLOYA DE GUTIÉRREZ | AB9: EN LA TIENDA DICONSA 34, EN FRENTE D | AD9: 70391 | AF9: EN OPERACION | AH9: 45377 | AI9: POLVO | AK9: CON VENTA DE BASICOS | AM9: 6 | AN9: TIENDA | AP9: 3 | AQ9: DICONSA | AR9: 3108 | AS9: MIGUEL ANGEL MARTINEZ PURA | AT9: 208935 | AU9: GARCIA MENDEZ MARIA | AV9: 0.375 | AW9: 0.58333333
A10: R | B10: TD | C10: P | D10: 4 | E10: 8 | F10: 6.5 | G10: 2002210100 | H10: 22101 | I10: 67 | J10: 20 | K10: 65 | L10: =J10+K10 -> 85 | M10: 22 | N10: COSOLTEPEC | O10: 1 | P10: COSOLTEPEC | R10: RURAL | T10: 3 | V10: MEDIA | X10: MIGUEL HIDALGO S/N | Z10: CENTRO, COSOLTEPEC | AB10: AVE. 16 DE SEPTIEMBRE Y AVE. 5 DE FE | AD10: 69020 | AF10: EN OPERACION | AH10: 44105 | AI10: POLVO | AK10: CON VENTA DE BASICOS | AM10: 6 | AN10: TIENDA | AP10: 3 | AQ10: DICONSA | AR10: 3128 | AS10: VIANNY YAZMIN VELASCO MATUS | AT10: 1 | AU10: NOMBRE CONCESIONARIO | AV10: 0.375 | AW10: 0.58333333
A11: R | B11: TD | C11: P | D11: 7 | E11: 3 | F11: 6.5 | G11: 2002810600 | H11: 28106 | I11: 33 | J11: 23 | K11: 25 | L11: =J11+K11 -> 48 | M11: 28 | N11: HEROICA CIUDAD DE EJUTLA DE CRESPO | O11: 7 | P11: MONTE DEL TORO | R11: RURAL | T11: 2 | V11: ALTA | X11: CENTRAL S/N | Z11: CENTRO MONTE DEL TORO | AB11: CALLE NINGUNO Y CALLE NINGUNO | AD11: 71502 | AF11: EN OPERACION | AH11: 43987 | AI11: POLVO | AK11: CON VENTA DE BASICOS | AM11: 6 | AN11: TIENDA | AP11: 3 | AQ11: DICONSA | AR11: 4517 | AS11: FLORES LOPEZ JUAN EDGAR | AT11: 1 | AU11: NOMBRE CONCESIONARIO | AV11: 0.375 | AW11: 0.54166667
A12: R | B12: TD | C12: P | D12: 6 | E12: 2 | F12: 6.5 | G12: 2003110400 | H12: 31104 | I12: 50 | J12: 38 | K12: 31 | L12: =J12+K12 -> 69 | M12: 31 | N12: TAMAZULÁPAM DEL ESPÍRITU SANTO | O12: 1 | P12: TAMAZULAPAM DEL ESPIRITU SANTO | R12: RURAL | T12: 2 | V12: ALTA | X12: PROGRESO S/N | Z12: CENTRO TAMAZULAPAN | AB12: CALLE ZEMPOALTEPETL Y CALLE NINGUNO | AD12: 70280 | AF12: EN OPERACION | AH12: 43815 | AI12: POLVO | AK12: CON VENTA DE BASICOS | AM12: 6 | AN12: TIENDA | AP12: 3 | AQ12: DICONSA | AR12: 3039 | AS12: SANTOS PINELO FLOR MAGDALENA | AT12: 1 | AU12: NOMBRE CONCESIONARIO | AV12: 0.375 | AW12: 0.54166667
A13: R | B13: TD | C13: P | D13: 4 | E13: 7 | F13: 6.5 | G13: 2003911400 | H13: 39114 | I13: 75 | J13: 41 | K13: 57 | L13: =J13+K13 -> 98 | M13: 39 | N13: HEROICA CIUDAD DE HUAJUAPAN DE LEÓN | O13: 15 | P13: EL MOLINO | R13: RURAL | T13: 2 | V13: ALTA | X13: GUADALUPE VÍCTORIA S/N | Z13: CENTRO, EL MOLINO | AB13: CALLE FERNANDO SOLANA GÓMEZ | AD13: 69009 | AF13: EN OPERACION | AH13: 44004 | AI13: POLVO | AK13: CON VENTA DE BASICOS | AM13: 6 | AN13: TIENDA | AP13: 3 | AQ13: DICONSA | AR13: 3146 | AS13: FELIPE ROMERO GONZALEZ | AT13: 1 | AU13: NOMBRE CONCESIONARIO | AV13: 0.375 | AW13: 0.54166667
... A26: R | B26: TD | C26: P | D26: 3 | E26: 3 | F26: 6.5 | G26: 2005310200 | H26: 53102 | I26: 25 | J26: 13 | K26: 30 | L26: =J26+K26 -> 43 | M26: 53 | N26: MAGDALENA TLACOTEPEC | O26: 1 | P26: MAGDALENA TLACOTEPEC | R26: RURAL | T26: 2 | V26: ALTA | X26: 3 DE MAYO S/N | Z26: MAGDALENA TLACOTEPEC | AB26: CALLE ITURBIDE Y CALLE EMILIANO ZAPA | AD26: 70746 | AF26: EN OPERACION | AH26: 44952 | AI26: POLVO | AK26: CON VENTA DE BASICOS | AM26: 6 | AN26: TIENDA | AP26: 3 | AQ26: DICONSA | AR26: 3148 | AS26: CARPIO RITO JOSE LEONARDO | AT26: 1 | AU26: NOMBRE CONCESIONARIO | AV26: 0.375 | AW26: 0.58333333
A27: R | B27: TD | C27: P | D27: 4 | E27: 9 | F27: 6.5 | G27: 2005510100 | H27: 55101 | I27: 140 | J27: 74 | K27: 133 | L27: =J27+K27 -> 207 | M27: 55 | N27: MARISCALA DE JUÁREZ | O27: 1 | P27: MARISCALA DE JUAREZ | R27: RURAL | T27: 3 | V27: MEDIA | X27: RICARDO FLORES MAGÓN SIN NUMERO | Z27: CENTRO | AB27: ENTRE CALLE BENITO JUÁREZ Y CALLE CO | AD27: 69250 | AF27: EN OPERACION | AH27: 40416 | AI27: POLVO | AK27: CON VENTA DE BASICOS | AM27: 6 | AN27: TIENDA | AP27: 3 | AQ27: DICONSA | AR27: 3142 | AS27: LORENA MAGDANELA MARTÍNEZ MARTÍNEZ | AT27: 1 | AU27: NOMBRE CONCESIONARIO
A28: R | B28: TD | C28: P | D28: 4 | E28: 9 | F28: 6.5 | G28: 2005510200 | H28: 55102 | I28: 51 | J28: 36 | K28: 43 | L28: =J28+K28 -> 79 | M28: 55 | N28: MARISCALA DE JUÁREZ | O28: 6 | P28: SAN PEDRO ATOYAC | R28: RURAL | T28: 2 | V28: ALTA | X28: BENITO JUÁREZ S/N | Z28: SAN PEDRO ATOYAC | AB28: EN LA TIENDA DICONSA NÚMERO 95, UNA | AD28: 69254 | AF28: EN OPERACION | AH28: 45337 | AI28: POLVO | AK28: CON VENTA DE BASICOS | AM28: 6 | AN28: TIENDA | AP28: 3 | AQ28: DICONSA | AR28: 3142 | AS28: LORENA MAGDANELA MARTÍNEZ MARTÍNEZ | AT28: 96152 | AU28: INES ANA GARCIA MORALES | AV28: 0.375 | AW28: 0.58333333
A29: R | B29: TD | C29: P | D29: 3 | E29: 4 | F29: 6.5 | G29: 2005710200 | H29: 57102 | I29: 150 | J29: 81 | K29: 109 | L29: =J29+K29 -> 190 | M29: 57 | N29: MATÍAS ROMERO AVENDAÑO | O29: 18 | P29: PALOMARES | R29: RURAL | T29: 2 | V29: ALTA | X29: SECTOR 4 S/N | Z29: CENTRO | AB29: A UN COSTADO DE LA TERMINAL DE AUTOB | AD29: 70312 | AF29: EN OPERACION | AH29: 35885 | AI29: POLVO | AK29: CON VENTA DE BASICOS | AM29: 6 | AN29: TIENDA | AP29: 3 | AQ29: DICONSA | AR29: 3108 | AS29: MIGUEL ANGEL MARTINEZ PURA | AT29: 1 | AU29: NOMBRE CONCESIONARIO | AV29: 0.33333333 | AW29: 0.58333333
A30: R | B30: TD | C30: P | D30: 3 | E30: 4 | F30: 6.5 | G30: 2005711200 | H30: 57112 | I30: 32 | J30: 36 | K30: 36 | L30: =J30+K30 -> 72 | M30: 57 | N30: MATÍAS ROMERO AVENDAÑO | O30: 21 | P30: EL PASO DE LAS MARAVILLAS | R30: RURAL | T30: 2 | V30: ALTA | X30: BENITO JUÁREZ S/N | Z30: EL PASO DE LAS MARAVILLAS | AB30: CALLE NORMA MONROY Y CALLE VICENTE G | AD30: 70300 | AF30: EN OPERACION | AH30: 44614 | AI30: POLVO | AK30: CON VENTA DE BASICOS | AM30: 6 | AN30: TIENDA | AP30: 3 | AQ30: DICONSA | AR30: 3108 | AS30: MIGUEL ANGEL MARTINEZ PURA | AT30: 1 | AU30: NOMBRE CONCESIONARIO | AV30: 0.375 | AW30: 0.58333333
A31: R | B31: TD | C31: P | D31: 3 | E31: 4 | F31: 6.5 | G31: 2005711300 | H31: 57113 | I31: 90 | J31: 61 | K31: 61 | L31: =J31+K31 -> 122 | M31: 57 | N31: MATÍAS ROMERO AVENDAÑO | O31: 207 | P31: COLONIA CUAUHTEMOC | R31: RURAL | T31: 4 | V31: BAJA | X31: CUAUHTÉMOC-CASA BLANCA S/N | Z31: COLONIA CUAUHTÉMOC | AB31: EN LA TIENDA DICONSA NÚM.113 A UN LA | AD31: 70317 | AF31: EN OPERACION | AH31: 45404 | AI31: POLVO | AK31: CON VENTA DE BASICOS | AM31: 6 | AN31: TIENDA | AP31: 3 | AQ31: DICONSA | AR31: 3108 | AS31: MIGUEL ANGEL MARTINEZ PURA | AT31: 208831 | AU31: LOPEZ FLORES MARIA TERESA | AV31: 0.375 | AW31: 0.58333333
A32: R | B32: TD | C32: P | D32: 7 | E32: 3 | F32: 6.5 | G32: 2005910600 | H32: 59106 | I32: 29 | J32: 21 | K32: 12 | L32: =J32+K32 -> 33 | M32: 59 | N32: MIAHUATLÁN DE PORFIRIO DÍAZ | O32: 6 | P32: GUIXE | R32: RURAL | T32: 2 | V32: ALTA | X32: FRANCISCO I. MADERO S/N | Z32: NINGUNO | AB32: CALLE BENITO JUÁREZ Y CALLE NINGUNO | AD32: 70800 | AF32: EN OPERACION | AH32: 43018 | AI32: POLVO | AK32: CON VENTA DE BASICOS | AM32: 6 | AN32: TIENDA | AP32: 3 | AQ32: DICONSA | AR32: 4517 | AS32: FLORES LOPEZ JUAN EDGAR | AT32: 1 | AU32: NOMBRE CONCESIONARIO | AV32: 0.375 | AW32: 0.5
A33: R | B33: TD | C33: P | D33: 7 | E33: 1 | F33: 6.5 | G33: 2005910800 | H33: 59108 | I33: 35 | J33: 24 | K33: 15 | L33: =J33+K33 -> 39 | M33: 59 | N33: MIAHUATLÁN DE PORFIRIO DÍAZ | O33: 18 | P33: SANTA CATARINA ROATINA | R33: RURAL | T33: 2 | V33: ALTA | X33: HIDALGO S/N | Z33: SANTA CATARINA ROATINA | AB33: CALLE DIAZ ORDAZ Y CALLE INDEPENDENC | AD33: 70803 | AF33: EN OPERACION | AH33: 43893 | AI33: POLVO | AK33: CON VENTA DE BASICOS | AM33: 6 | AN33: TIENDA | AP33: 3 | AQ33: DICONSA | AR33: 3047 | AS33: ANAY MARGARITA CRUZ RAMOS | AT33: 1 | AU33: NOMBRE CONCESIONARIO | AV33: 0.375 | AW33: 0.5
A34: R | B34: TD | C34: P | D34: 7 | E34: 2 | F34: 6.5 | G34: 2005910900 | H34: 59109 | I34: 48 | J34: 29 | K34: 36 | L34: =J34+K34 -> 65 | M34: 59 | N34: MIAHUATLÁN DE PORFIRIO DÍAZ | O34: 4 | P34: BRAMADEROS | R34: RURAL | T34: 2 | V34: ALTA | X34: NINGUNO S/N | Z34: CENTRO BRAMADEROS | AB34: CALLE NINGUNO Y CALLE NINGUNO | AD34: 70800 | AF34: EN OPERACION | AH34: 43965 | AI34: POLVO | AK34: CON VENTA DE BASICOS | AM34: 6 | AN34: TIENDA | AP34: 3 | AQ34: DICONSA | AR34: 3031 | AS34: CRUZ CORTES MARCO ANTONIO | AT34: 1 | AU34: NOMBRE CONCESIONARIO | AV34: 0.33333333 | AW34: 0.58333333
A35: R | B35: TD | C35: P | D35: 7 | E35: 1 | F35: 6.5 | G35: 2005911100 | H35: 59111 | I35: 70 | J35: 70 | K35: 47 | L35: =J35+K35 -> 117 | M35: 59 | N35: MIAHUATLÁN DE PORFIRIO DÍAZ | O35: 71 | P35: LA PILA | R35: RURAL | T35: 2 | V35: ALTA | X35: HIDALGO S/N | Z35: CENTRO | AB35: A UN LADO DE LA CALLE PRINCIPAL | AD35: 70805 | AF35: EN OPERACION | AH35: 44222 | AI35: POLVO | AK35: CON VENTA DE BASICOS | AM35: 6 | AN35: TIENDA | AP35: 3 | AQ35: DICONSA | AR35: 3047 | AS35: ANAY MARGARITA CRUZ RAMOS | AT35: 1 | AU35: NOMBRE CONCESIONARIO | AV35: 0.375 | AW35: 0.58333333
A36: R | B36: TD | C36: P | D36: 7 | E36: 2 | F36: 6.5 | G36: 2005911200 | H36: 59112 | I36: 19 | J36: 8 | K36: 20 | L36: =J36+K36 -> 28 | M36: 59 | N36: MIAHUATLÁN DE PORFIRIO DÍAZ | O36: 31 | P36: EL GUAYABO TEPEHUAJE | R36: RURAL | T36: 2 | V36: ALTA | X36: NINGUNO S/N | Z36: EL GUAYABO TEPEHUAJE | AB36: CALLE NINGUNO Y CALLE NINGUNO | AD36: 70800 | AF36: EN OPERACION | AH36: 44825 | AI36: POLVO | AK36: CON VENTA DE BASICOS | AM36: 6 | AN36: TIENDA | AP36: 3 | AQ36: DICONSA | AR36: 3031 | AS36: CRUZ CORTES MARCO ANTONIO | AT36: 1 | AU36: NOMBRE CONCESIONARIO | AV36: 0.375 | AW36: 0.58333333
A37: R | B37: TD | C37: P | D37: 7 | E37: 2 | F37: 6.5 | G37: 2005911300 | H37: 59113 | I37: 35 | J37: 29 | K37: 14 | L37: =J37+K37 -> 43 | M37: 59 | N37: MIAHUATLÁN DE PORFIRIO DÍAZ | O37: 16 | P37: SAN PEDRO COATLAN | R37: RURAL | T37: 2 | V37: ALTA | X37: 16 DE SEPTIEMBRE S/N | Z37: SAN PEDRO COATLAN | AB37: CALLE VICENTE GUERRERO Y PRIV. DE GU | AD37: 70802 | AF37: EN OPERACION | AH37: 44827 | AI37: POLVO | AK37: CON VENTA DE BASICOS | AM37: 6 | AN37: TIENDA | AP37: 3 | AQ37: DICONSA | AR37: 3031 | AS37: CRUZ CORTES MARCO ANTONIO | AT37: 1 | AU37: NOMBRE CONCESIONARIO | AV37: 0.375 | AW37: 0.58333333
A38: R | B38: TD | C38: P | D38: 7 | E38: 2 | F38: 6.5 | G38: 2005911400 | H38: 59114 | I38: 57 | J38: 21 | K38: 48 | L38: =J38+K38 -> 69 | M38: 59 | N38: MIAHUATLÁN DE PORFIRIO DÍAZ | O38: 3 | P38: AGUA DE SOL | R38: RURAL | T38: 2 | V38: ALTA | X38: MORELOS S/N | Z38: AGUA DE SOL | AB38: PLANTA BAJA DE LA AGENCIA MUNICIPAL | AD38: 70802 | AF38: EN OPERACION | AH38: 45957 | AI38: POLVO | AK38: CON VENTA DE BASICOS | AM38: 6 | AN38: TIENDA | AP38: 3 | AQ38: DICONSA | AR38: 4517 | AS38: FLORES LOPEZ JUAN EDGAR | AT38: 208773 | AU38: GARCIA VELASCO MONICA ELISA | AV38: 0.375 | AW38: 0.58333333
A39: R | B39: TD | C39: P | D39: 7 | E39: 1 | F39: 6.5 | G39: 2005911500 | H39: 59115 | I39: 52 | J39: 30 | K39: 38 | L39: =J39+K39 -> 68 | M39: 59 | N39: MIAHUATLÁN DE PORFIRIO DÍAZ | O39: 1 | P39: MIAHUATLAN DE PORFIRIO DIAZ | R39: RURAL | T39: 2 | V39: ALTA | X39: ZARAGOZA NUM. 317 | Z39: SAN FRANCISCO | AB39: EN LA TIENDA DEL BIENESTAR NUMERO 13 | AD39: 70805 | AF39: EN OPERACION | AH39: 45992 | AI39: POLVO | AK39: CON VENTA DE BASICOS | AM39: 6 | AN39: TIENDA | AP39: 3 | AQ39: DICONSA | AR39: 3047 | AS39: ANAY MARGARITA CRUZ RAMOS | AT39: 208831 | AU39: LOPEZ FLORES MARIA TERESA | AV39: 0.375 | AW39: 0.58333333
... A46: R | B46: TD | C46: P | D46: 2 | E46: 7 | F46: 6.5 | G46: 2007311500 | H46: 73115 | I46: 104 | J46: 32 | K46: 91 | L46: =J46+K46 -> 123 | M46: 73 | N46: PUTLA VILLA DE GUERRERO | O46: 4 | P46: ASUNCION ATOYAQUILLO | R46: RURAL | T46: 2 | V46: ALTA | X46: 6 DE SEPTIEMBRE S/N | Z46: ASUNCIÓN ATOYAQUILLO | AB46: FRENTE A LA REFACCIONARIA TAURO | AD46: 71020 | AF46: EN OPERACION | AH46: 46009 | AI46: POLVO | AK46: CON VENTA DE BASICOS | AM46: 6 | AN46: TIENDA | AP46: 3 | AQ46: DICONSA | AR46: 3123 | AS46: GABRIELA ARIZBETH DIAZ SANTIAGO | AT46: 208781 | AU46: SANCHEZ HERNANDEZ LUCILA | AV46: 0.375 | AW46: 0.58333333
A47: R | B47: TD | C47: P | D47: 2 | E47: 7 | F47: 6.5 | G47: 2007610100 | H47: 76101 | I47: 78 | J47: 62 | K47: 60 | L47: =J47+K47 -> 122 | M47: 76 | N47: LA REFORMA | O47: 1 | P47: LA REFORMA | R47: RURAL | T47: 3 | V47: MEDIA | X47: CONSTITUCION S/N | Z47: CENTRO | AB47: HIDALGO Y AURORA | AD47: 77777 | AF47: EN OPERACION | AH47: 41017 | AI47: POLVO | AK47: CON VENTA DE BASICOS | AM47: 6 | AN47: TIENDA | AP47: 3 | AQ47: DICONSA | AR47: 3123 | AS47: GABRIELA ARIZBETH DIAZ SANTIAGO | AT47: 1 | AU47: NOMBRE CONCESIONARIO
A48: R | B48: TD | C48: P | D48: 2 | E48: 7 | F48: 6.5 | G48: 2007610200 | H48: 76102 | I48: 61 | J48: 41 | K48: 53 | L48: =J48+K48 -> 94 | M48: 76 | N48: LA REFORMA | O48: 2 | P48: ESTANZUELA GRANDE | R48: RURAL | T48: 2 | V48: ALTA | X48: SIN NOMBRE S/N | Z48: ESTANZUELA GRANDE | AB48: TIENDA DICONSA NUMERO 42 DE LA POBLA | AD48: 71081 | AF48: EN OPERACION | AH48: 45642 | AI48: POLVO | AK48: CON VENTA DE BASICOS | AM48: 6 | AN48: TIENDA | AP48: 3 | AQ48: DICONSA | AR48: 3123 | AS48: GABRIELA ARIZBETH DIAZ SANTIAGO | AT48: 208653 | AU48: PERALTA REYES RAMIRO | AV48: 0.375 | AW48: 0.58333333
A49: R | B49: TD | C49: P | D49: 2 | E49: 6 | F49: 6.5 | G49: 2008210200 | H49: 82102 | I49: 31 | J49: 19 | K49: 29 | L49: =J49+K49 -> 48 | M49: 82 | N49: SAN AGUSTÍN CHAYUCO | O49: 1 | P49: SAN AGUSTIN CHAYUCO | R49: RURAL | T49: 2 | V49: ALTA | X49: RAFAEL RAMÍREZ S/N | Z49: CENTRO | AB49: ENTRE CALLE MORELOS Y CALLE NICOLAS | AD49: 71764 | AF49: EN OPERACION | AH49: 43388 | AI49: POLVO | AK49: CON VENTA DE BASICOS | AM49: 6 | AN49: TIENDA | AP49: 3 | AQ49: DICONSA | AR49: 3102 | AS49: SULEMA CRUZ LOPEZ | AT49: 1 | AU49: NOMBRE CONCESIONARIO | AV49: 0.375 | AW49: 0.58333333
A50: R | B50: TD | C50: P | D50: 2 | E50: 6 | F50: 6.5 | G50: 2008210300 | H50: 82103 | I50: 25 | J50: 24 | K50: 24 | L50: =J50+K50 -> 48 | M50: 82 | N50: SAN AGUSTÍN CHAYUCO | O50: 6 | P50: YUCUTACO | R50: RURAL | T50: 2 | V50: ALTA | X50: LUIS DONALDO COLOSIO S/N | Z50: CENTRO | AB50: CALLE NINGUNO E INDEPENDENCIA. EN EL | AD50: 71768 | AF50: EN OPERACION | AH50: 44375 | AI50: POLVO | AK50: CON VENTA DE BASICOS | AM50: 6 | AN50: TIENDA | AP50: 3 | AQ50: DICONSA | AR50: 3102 | AS50: SULEMA CRUZ LOPEZ | AT50: 1 | AU50: NOMBRE CONCESIONARIO | AV50: 0.375 | AW50: 0.58333333
A51: R | B51: TD | C51: P | D51: 4 | E51: 1 | F51: 6.5 | G51: 2008810400 | H51: 88104 | I51: 69 | J51: 47 | K51: 60 | L51: =J51+K51 -> 107 | M51: 88 | N51: SAN ANDRÉS CABECERA NUEVA | O51: 1 | P51: SAN ANDRES CABECERA NUEVA | R51: RURAL | T51: 2 | V51: ALTA | X51: GUADALUPE VICTORIA S/N | Z51: CENTRO | AB51: CERRADA DE GUERRERO Y CALLE VICENTE | AD51: 71170 | AF51: EN OPERACION | AH51: 43398 | AI51: POLVO | AK51: CON VENTA DE BASICOS | AM51: 6 | AN51: TIENDA | AP51: 3 | AQ51: DICONSA | AR51: 3150 | AS51: ELIEL DAVID CASTELLANOS RAMIREZ | AT51: 1 | AU51: NOMBRE CONCESIONARIO | AV51: 0.375 | AW51: 0.54166667
A52: R | B52: TD | C52: P | D52: 2 | E52: 6 | F52: 6.5 | G52: 2009010100 | H52: 90101 | I52: 166 | J52: 104 | K52: 122 | L52: =J52+K52 -> 226 | M52: 90 | N52: SAN ANDRÉS HUAXPALTEPEC | O52: 1 | P52: SAN ANDRES HUAXPALTEPEC | R52: RURAL | T52: 2 | V52: ALTA | X52: AV PRINCIPAL Y CARRETERA COSTERA | Z52: CENTRO | AB52: ENTRE LA CALLE 14 DE FEBRERO Y CALLE | AD52: 71770 | AF52: EN OPERACION | AH52: 34731 | AI52: POLVO | AK52: CON VENTA DE BASICOS | AM52: 6 | AN52: TIENDA | AP52: 3 | AQ52: DICONSA | AR52: 3102 | AS52: SULEMA CRUZ LOPEZ | AT52: 1 | AU52: NOMBRE CONCESIONARIO | AV52: 0.33333333 | AW52: 0.54166667
A53: R | B53: TD | C53: P | D53: 4 | E53: 3 | F53: 6.5 | G53: 2009310200 | H53: 93102 | I53: 55 | J53: 14 | K53: 55 | L53: =J53+K53 -> 69 | M53: 93 | N53: SAN ANDRÉS LAGUNAS | O53: 1 | P53: SAN ANDRES LAGUNAS | R53: RURAL | T53: 2 | V53: ALTA | X53: INDEPENDENCIA S/N | Z53: CENTRO, SAN ANDRÉS LAGUNA | AB53: CALLE BENITO JUAREZ Y CALLE HIDALGO | AD53: 69550 | AF53: EN OPERACION | AH53: 44105 | AI53: POLVO | AK53: CON VENTA DE BASICOS | AM53: 6 | AN53: TIENDA | AP53: 3 | AQ53: DICONSA | AR53: 3151 | AS53: SUSANA MENDOZA LOPEZ | AT53: 1 | AU53: NOMBRE CONCESIONARIO | AV53: 0.375 | AW53: 0.58333333
A54: R | B54: TD | C54: P | D54: 6 | E54: 1 | F54: 6.5 | G54: 2009710100 | H54: 97101 | I54: 51 | J54: 32 | K54: 32 | L54: =J54+K54 -> 64 | M54: 97 | N54: SAN ANDRÉS SOLAGA | O54: 3 | P54: SANTO DOMINGO YOJOVI | R54: RURAL | T54: 2 | V54: ALTA | X54: INDEPENDENCIA S/N | Z54: SANTO DOMINGO YOJOVI | AB54: EN LA TIENDA DICONSA NÚMERO 98,A UN | AD54: 68844 | AF54: EN OPERACION | AH54: 45337 | AI54: POLVO | AK54: CON VENTA DE BASICOS | AM54: 6 | AN54: TIENDA | AP54: 3 | AQ54: DICONSA | AR54: 3032 | AS54: AQUINO SANTIAGO MARIA GUADALUPE | AT54: 14553 | AU54: SILVIA CORTES RAMIREZ | AV54: 0.375 | AW54: 0.58333333
A55: R | B55: TD | C55: P | D55: 4 | E55: 4 | F55: 6.5 | G55: 2010014400 | H55: 100144 | I55: 224 | J55: 117 | K55: 240 | L55: =J55+K55 -> 357 | M55: 540 | N55: VILLA DE TAMAZULÁPAM DEL PROGRESO | O55: 1 | P55: VILLA DE TAMAZULAPAM DEL PROGRESO | R55: RURAL | T55: 5 | V55: MUY BAJA | X55: PLAZA DE LA CONSTITUCIÓN S/N | Z55: CENTRO | AB55: A DOS CUADRAS DE LA IGLESIA | AD55: 69510 | AF55: EN OPERACION | AH55: 33307 | AI55: POLVO | AK55: CON VENTA DE BASICOS | AM55: 6 | AN55: TIENDA | AP55: 3 | AQ55: DICONSA | AR55: 3147 | AS55: DULCE ANDREA CASTELLANOS VAZQUEZ | AT55: 1 | AU55: NOMBRE CONCESIONARIO
A56: R | B56: TD | C56: P | D56: 4 | E56: 2 | F56: 6.5 | G56: 2010042600 | H56: 100426 | I56: 411 | J56: 253 | K56: 336 | L56: =J56+K56 -> 589 | M56: 397 | N56: HEROICA CIUDAD DE TLAXIACO | O56: 30 | P56: BARRIO SAN SEBASTIAN | R56: RURAL | T56: 3 | V56: MEDIA | X56: FRESNOS NUMERO 3 | Z56: BARRIO SAN SEBASTIAN | AB56: ENTRE LA CALLE NOGAL Y CALLE CHABACA | AD56: 69800 | AF56: EN OPERACION | AH56: 33329 | AI56: POLVO | AK56: CON VENTA DE BASICOS | AM56: 6 | AN56: TIENDA | AP56: 3 | AQ56: DICONSA | AR56: 3073 | AS56: PACHECO HERNANDEZ VERONICA PATRICIA | AT56: 1 | AU56: NOMBRE CONCESIONARIO | AV56: 0.375 | AW56: 0.58333333
A57: R | B57: TD | C57: P | D57: 7 | E57: 4 | F57: 6.5 | G57: 2010110200 | H57: 101102 | I57: 17 | J57: 13 | K57: 13 | L57: =J57+K57 -> 26 | M57: 28 | N57: HEROICA CIUDAD DE EJUTLA DE CRESPO | O57: 18 | P57: SANTA CRUZ NEXILA | R57: RURAL | T57: 2 | V57: ALTA | X57: CALLE HIDALGO SIN NUMERO | Z57: RANCHERIA SANTA CRUZ NEXILA | AB57: CALLE JUAREZ Y CALLE NINGUNO | AD57: 71502 | AF57: EN OPERACION | AH57: 42604 | AI57: POLVO | AK57: CON VENTA DE BASICOS | AM57: 6 | AN57: TIENDA | AP57: 3 | AQ57: DICONSA | AR57: 3061 | AS57: VERONICA JOSEFINA GOMEZ RODRIGUEZ | AT57: 1 | AU57: NOMBRE CONCESIONARIO | AV57: 0.375 | AW57: 0.58333333
A58: R | B58: TD | C58: P | D58: 7 | E58: 4 | F58: 6.5 | G58: 2010410300 | H58: 104103 | I58: 38 | J58: 12 | K58: 42 | L58: =J58+K58 -> 54 | M58: 104 | N58: SAN ANTONINO EL ALTO | O58: 3 | P58: SAN FERNANDO DE MATAMOROS | R58: RURAL | T58: 2 | V58: ALTA | X58: PORFIRIO DÍAZ S/N | Z58: CENTRO SAN FERNANDO DE MATAMOROS | AB58: CALLE MORELOS Y CALLE NINGUNO | AD58: 71346 | AF58: EN OPERACION | AH58: 44172 | AI58: POLVO | AK58: CON VENTA DE BASICOS | AM58: 6 | AN58: TIENDA | AP58: 3 | AQ58: DICONSA | AR58: 3061 | AS58: VERONICA JOSEFINA GOMEZ RODRIGUEZ | AT58: 1 | AU58: NOMBRE CONCESIONARIO | AV58: 0.375 | AW58: 0.58333333
...

Sheet POR ALMACEN
A1: LECHE PARA EL BIENESTAR, S.A. DE C.V.
A2: GERENCIA ESTATAL OAXACA
A3: DEPARTAMENTO DE DISTRIBUCION Y TRANSPORTACION
A4: REQUERIMIENTO DE LECHE EN POLVO CORRESPONDIENTE AL MES DE JUNIO DEL 2026.
A5: LECHERIAS INCORPORADAS AL CONVENIO LECHE PARA EL BIENESTAR-ALIMENTACION PARA EL BIENESTAR 6.50 X LITRO
L6: PADRON DE BENEFICIARIOS. AL CIERRE DE ABRIL 2026
A7: LECHERÍA | B7: TIENDA | D7: PADRÓN | F7: DOT. | G7: Envio | H7: EXIST. | I7: EXISTENCIA | K7: Envio Program. | L7: EXIST.ESTIMADA | M7: % AJUSTE | O7: SOBRANTE | P7: CAJAS | Q7: GUIA DIST.
A8: NÚM. | B8: No. | C8: L O C A L I D A D | D8: FAM. | E8: BENEF. | F8: MEN. | G8: ABRIL | H8: EN | I8: CAJ. | J8: SOB. | K8: MAYO | L8: INICIO | M8: DOT. TEORICA | O8: ESTIM. P/ | P8: SOLIC. X | Q8: JUNIO
F9: TEORICA | H9: ALMACEN | M9: % | N9: CAJAS | P9: SUPERV.
B11: ALMACEN RURAL : CHALCATONGO
A14: 88104 | B14: 23 | C14: SAN ANDRES CABECERA NUEVA | D14: 69 | E14: 107 | F14: =E14*0.666*24/72 | G14: 0 | H14: 0 | I14: 0 | J14: 0 | K14: 0 | L14: 0 | M14: 0 | N14: 0 | O14: 0 | Q14: =+P14
A15: 120423 | B15: 15 | C15: CHALCATONGO DE HIDALGO | D15: 307 | E15: 428 | F15: =E15*0.666*24/72 | G15: 0 | H15: 0 | I15: 0 | J15: 0 | K15: 0 | L15: 0 | M15: 0 | N15: 0 | O15: 0 | Q15: =+P15
A16: 133106 | B16: 105 | C16: SAN ESTEBAN ATATLAHUACA | D16: 213 | E16: 267 | F16: =E16*0.666*24/72 | G16: 0 | H16: 0 | I16: 0 | J16: 0 | K16: 0 | L16: 0 | M16: 0 | N16: 0 | O16: 0 | Q16: =+P16
A17: 269103 | B17: 106 | C17: SAN MIGUEL EL GRANDE | D17: 60 | E17: 81 | F17: =E17*0.666*24/72 | G17: 0 | H17: 0 | I17: 0 | J17: 0 | K17: 0 | L17: 0 | M17: 0 | N17: 0 | O17: 0 | Q17: =+P17
A18: 320101 | B18: 4 | C18: SAN PEDRO MOLINOS | D18: 53 | E18: 74 | F18: =E18*0.666*24/72 | G18: 0 | H18: 0 | I18: 0 | J18: 0 | K18: 0 | L18: 0 | M18: 0 | N18: 0 | O18: 0 | Q18: =+P18
A19: 371102 | B19: 119 | C19: SANTA CATARINA TICU | D19: 76 | E19: 96 | F19: =E19*0.666*24/72 | G19: 0 | H19: 0 | I19: 0 | J19: 0 | K19: 0 | L19: 0 | M19: 0 | N19: 0 | O19: 0 | Q19: =+P19
A20: 510102 | B20: 10 | C20: SANTO DOMINGO IXCATL N | D20: 56 | E20: 64 | F20: =E20*0.666*24/72 | G20: 0 | H20: 0 | I20: 0 | J20: 0 | K20: 0 | L20: 0 | M20: 0 | N20: 0 | O20: 0 | Q20: =+P20
A22: T O T A L | C22: =COUNTA(A14:A20) | D22: =SUM(D14:D20) | E22: =SUM(E14:E20) | F22: =SUM(F14:F20) | G22: =SUM(G14:G20) | H22: =SUM(H14:H20) | I22: =SUM(I14:I20) | J22: =SUM(J14:J20) | K22: =SUM(K14:K20) | ... Q22: =SUM(Q14:Q20)
A23: OBSERVACIONES:
P24: TOTAL A RECIBIR EN ALMACEN: | Q24: =Q22
B27: ALMACEN RURAL : COIXTLAHUACA
A30: 100144 | B30: 50 | C30: COL CENTRO | D30: 210 | E30: 341 | F30: =E30*0.666*24/72 | G30: 0 | H30: 0 | I30: 0 | J30: 0 | K30: 0 | L30: 0 | M30: 0 | N30: 0 | O30: 0 | Q30: =+P30
A31: 120438 | B31: 65 | C31: TEPELMEME VILLA DE MORELOS | D31: 136 | E31: 205 | F31: =E31*0.666*24/72 | G31: 0 | H31: 0 | I31: 0 | J31: 0 | K31: 0 | L31: 0 | M31: 0 | N31: 0 | O31: 0 | Q31: =+P31
A32: 283101 | B32: 66 | C32: SAN MIGUEL TEQUIXTEPEC | D32: 91 | E32: 127 | F32: =E32*0.666*24/72 | G32: 0 | H32: 0 | I32: 0 | J32: 0 | K32: 0 | L32: 0 | M32: 0 | N32: 0 | O32: 0 | Q32: =+P32
A33: 422101 | B33: 23 | C33: SANTA MARIA NATIVITAS | D33: 58 | E33: 79 | F33: =E33*0.666*24/72 | G33: 0 | H33: 0 | I33: 0 | J33: 0 | K33: 0 | L33: 0 | M33: 0 | N33: 0 | O33: 0 | Q33: =+P33
A34: 552101 | B34: 27 | C34: TLACOTEPEC PLUMAS | D34: 53 | E34: 80 | F34: =E34*0.666*24/72 | G34: 0 | H34: 0 | I34: 0 | J34: 0 | K34: 0 | L34: 0 | M34: 0 | N34: 0 | O34: 0 | Q34: =+P34
A35: 556101 | B35: 10 | C35: LA TRINIDAD VISTA HERMOSA | D35: 69 | E35: 107 | F35: =E35*0.666*24/72 | G35: 0 | H35: 0 | I35: 0 | J35: 0 | K35: 0 | L35: 0 | M35: 0 | N35: 0 | O35: 0 | Q35: =+P35
A37: T O T A L | C37: =COUNTA(A30:A35) | D37: =SUM(D30:D35) | E37: =SUM(E30:E35) | F37: =SUM(F30:F35) | G37: =SUM(G30:G35) | H37: =SUM(H30:H35) | I37: =SUM(I30:I35) | J37: =SUM(J30:J35) | K37: =SUM(K30:K35) | ... Q37: =SUM(Q30:Q35)
A38: OBSERVACIONES:
P39: TOTAL A RECIBIR EN ALMACEN: | Q39: =Q37
B42: ALMACEN RURAL : CONSTANCIA DEL ROSARIO
A45: 73101 | B45: 46 | C45: SANTIAGO AMATE COLORADO | D45: 49 | E45: 83 | F45: =E45*0.666*24/72 | G45: 0 | H45: 0 | I45: 0 | J45: 0 | K45: 0 | L45: 0 | M45: 0 | N45: 0 | O45: 0 | Q45: =+P45
A46: 73113 | B46: 13 | C46: SAN PEDRO SINIYUVI | D46: 66 | E46: 79 | F46: =E46*0.666*24/72 | G46: 0 | H46: 0 | I46: 0 | J46: 0 | K46: 0 | L46: 0 | M46: 0 | N46: 0 | O46: 0 | Q46: =+P46
A47: 73114 | B47: 9 | C47: SAN ANDRES CHICAHUAXTLA | D47: 68 | E47: 81 | F47: =E47*0.666*24/72 | G47: 0 | H47: 0 | I47: 0 | J47: 0 | K47: 0 | L47: 0 | M47: 0 | N47: 0 | O47: 0 | Q47: =+P47
A48: 73115 | B48: 31 | C48: ASUNCION ATOYAQUILLO | D48: 101 | E48: 120 | F48: =E48*0.666*24/72 | G48: 0 | H48: 0 | I48: 0 | J48: 0 | K48: 0 | L48: 0 | M48: 0 | N48: 0 | O48: 0 | Q48: =+P48
A49: 76101 | B49: 33 | C49: LA REFORMA | D49: 78 | E49: 123 | F49: =E49*0.666*24/72 | G49: 0 | H49: 0 | I49: 0 | J49: 0 | K49: 0 | L49: 0 | M49: 0 | N49: 0 | O49: 0 | Q49: =+P49
A50: 76102 | B50: 42 | C50: ESTANZUELA GRANDE | D50: 61 | E50: 94 | F50: =E50*0.666*24/72 | G50: 0 | H50: 0 | I50: 0 | J50: 0 | K50: 0 | L50: 0 | M50: 0 | N50: 0 | O50: 0 | Q50: =+P50
A51: 120347 | B51: 79 | C51: PUTLA DE GUERRERO | D51: 485 | E51: 705 | F51: =E51*0.666*24/72 | G51: 0 | H51: 0 | I51: 0 | J51: 0 | K51: 0 | L51: 0 | M51: 0 | N51: 0 | O51: 0 | Q51: =+P51
A52: 120427 | B52: 93 | C52: NUEVO TENOCHTITLAN | D52: 56 | E52: 80 | F52: =E52*0.666*24/72 | G52: 0 | H52: 0 | I52: 0 | J52: 0 | K52: 0 | L52: 0 | M52: 0 | N52: 0 | O52: 0 | Q52: =+P52
A53: 120535 | B53: 24 | C53: SANTA MARIA ZACATEPEC | D53: 309 | E53: 495 | F53: =E53*0.666*24/72 | G53: 0 | H53: 0 | I53: 0 | J53: 0 | K53: 0 | L53: 0 | M53: 0 | N53: 0 | O53: 0 | Q53: =+P53
...

Sheet TOTAL
A1: LECHE PARA EL BIENESTAR, S.A. DE C.V.
A2: GERENCIA ESTATAL OAXACA
A3: DEPARTAMENTO DE DISTRIBUCIÓN Y TRANSPORTACIÓN
A4: =+'POR ALMACEN'!A4 -> REQUERIMIENTO DE LECHE EN POLVO CORRESPONDIENTE AL MES DE JUNIO DEL 2026.
A5: LECHERIAS INCORPORADAS AL CONVENIO LECHE PARA EL BIENESTAR-ALIMENTACION PARA EL BIENESTAR Precio $6.50 Lt. COD:1360
A7: ALMACEN DICONSA | C7: NUMERO DE TIENDAS | D7: PADRÓN | F7: DOTACION MENSUAL TEOR. | G7: SOBRANTE EN ALMACEN RURAL | H7: * REQUERIMIENTO * | J7: TOTALES POR SUCURSALES RURALES
D8: FAM. | E8: BENEF. | H8: CAJAS | I8: CAJAS A ENVIAR A ALMC. RURAL
A11: SUCURSAL HUAJUAPAN | J11: =SUM(I13:I20)
B13: CHALCATONGO | C13: =+'POR ALMACEN'!C22 | D13: =+'POR ALMACEN'!D22 | E13: =+'POR ALMACEN'!E22 | F13: =+'POR ALMACEN'!F22 | G13: 0 | H13: =+'POR ALMACEN'!P22 | I13: =H13-G13
B14: COIXTLAHUACA | C14: =+'POR ALMACEN'!C37 | D14: =+'POR ALMACEN'!D37 | E14: =+'POR ALMACEN'!E37 | F14: =+'POR ALMACEN'!F37 | G14: 0 | H14: =+'POR ALMACEN'!P37 | I14: =H14-G14
B15: CONSTANCIA DEL ROSARIO | C15: =+'POR ALMACEN'!C63 | D15: =+'POR ALMACEN'!D63 | E15: =+'POR ALMACEN'!E63 | F15: =+'POR ALMACEN'!F63 | G15: 0 | H15: =+'POR ALMACEN'!P63 | I15: =H15-G15
B16: HUAJOLOTITLAN | C16: =+'POR ALMACEN'!C85 | D16: =+'POR ALMACEN'!D85 | E16: =+'POR ALMACEN'!E85 | F16: =+'POR ALMACEN'!F85 | G16: 0 | H16: =+'POR ALMACEN'!P85 | I16: =H16-G16
B17: TACACHE DE MINA | C17: =+'POR ALMACEN'!C97 | D17: =+'POR ALMACEN'!D97 | E17: =+'POR ALMACEN'!E97 | F17: =+'POR ALMACEN'!F97 | G17: 0 | H17: =+'POR ALMACEN'!P97 | I17: =H17-G17
B18: TLAXIACO | C18: =+'POR ALMACEN'!C124 | D18: =+'POR ALMACEN'!D124 | E18: =+'POR ALMACEN'!E124 | F18: =+'POR ALMACEN'!F124 | G18: 0 | H18: =+'POR ALMACEN'!P124 | I18: =H18-G18
B19: TECOMAXTLAHUACA | C19: =+'POR ALMACEN'!C135 | D19: =+'POR ALMACEN'!D135 | E19: =+'POR ALMACEN'!E135 | F19: =+'POR ALMACEN'!F135 | G19: 0 | H19: =+'POR ALMACEN'!P135 | I19: =H19-G19
B20: YANHUITLAN | C20: =+'POR ALMACEN'!C156 | D20: =+'POR ALMACEN'!D156 | E20: =+'POR ALMACEN'!E156 | F20: =+'POR ALMACEN'!F156 | G20: 0 | H20: =+'POR ALMACEN'!P156 | I20: =H20-G20
A22: SUCURSAL ISTMO-COSTA | J22: =SUM(I24:I33)
B24: MORRO MAZATAN | C24: =+'POR ALMACEN'!C174 | D24: =+'POR ALMACEN'!D174 | E24: =+'POR ALMACEN'!E174 | F24: =+'POR ALMACEN'!F174 | G24: 0 | H24: =+'POR ALMACEN'!P174 | I24: =H24-G24
B25: PALOMARES | C25: =+'POR ALMACEN'!C194 | D25: =+'POR ALMACEN'!D194 | E25: =+'POR ALMACEN'!E194 | F25: =+'POR ALMACEN'!F194 | G25: 0 | H25: =+'POR ALMACEN'!P194 | I25: =H25-G25
B26: SANTIAGO LAOLLAGA | C26: =+'POR ALMACEN'!C210 | D26: =+'POR ALMACEN'!D210 | E26: =+'POR ALMACEN'!E210 | F26: =+'POR ALMACEN'!F210 | G26: 0 | H26: =+'POR ALMACEN'!P210 | I26: =H26-G26
B27: SANTIAGO NILTEPEC | C27: =+'POR ALMACEN'!C242 | D27: =+'POR ALMACEN'!D242 | E27: =+'POR ALMACEN'!E242 | F27: =+'POR ALMACEN'!F242 | G27: 0 | H27: =+'POR ALMACEN'!P242 | I27: =H27-G27
B28: EL TOMATAL | C28: =+'POR ALMACEN'!C266 | D28: =+'POR ALMACEN'!D266 | E28: =+'POR ALMACEN'!E266 | F28: =+'POR ALMACEN'!F266 | G28: 0 | H28: =+'POR ALMACEN'!P266 | I28: =H28-G28
B29: SAN ANDRES HUAXPALTEPEC | C29: =+'POR ALMACEN'!C304 | D29: =+'POR ALMACEN'!D304 | E29: =+'POR ALMACEN'!E304 | F29: =+'POR ALMACEN'!F304 | G29: 0 | H29: =+'POR ALMACEN'!P304 | I29: =H29-G29
B30: SANTA MARIA HUATULCO | C30: =+'POR ALMACEN'!C323 | D30: =+'POR ALMACEN'!D323 | E30: =+'POR ALMACEN'!E323 | F30: =+'POR ALMACEN'!F323 | G30: 0 | H30: =+'POR ALMACEN'!P323 | I30: =H30-G30
B31: LA REFORMA YAUTEPEC | C31: =+'POR ALMACEN'!C339 | D31: =+'POR ALMACEN'!D339 | E31: =+'POR ALMACEN'!E339 | F31: =+'POR ALMACEN'!F339 | G31: 0 | H31: =+'POR ALMACEN'!P339 | I31: =H31-G31
B32: LOS IDEALES | C32: =+'POR ALMACEN'!C348 | D32: =+'POR ALMACEN'!D348 | E32: =+'POR ALMACEN'!E348 | F32: =+'POR ALMACEN'!F348 | G32: 0 | H32: =+'POR ALMACEN'!P348 | I32: =H32-G32
B33: PUEBLO NUEVO, TUX. | C33: =+'POR ALMACEN'!C368 | D33: =+'POR ALMACEN'!D368 | E33: =+'POR ALMACEN'!E368 | F33: =+'POR ALMACEN'!F368 | G33: 0 | H33: =+'POR ALMACEN'!P368 | I33: =H33-G33
A35: SUCURSAL V. CENTRAL | J35: =SUM(I37:I48)
B37: VALLES CENTRALES | C37: =+'POR ALMACEN'!C382 | D37: =+'POR ALMACEN'!D382 | E37: =+'POR ALMACEN'!E382 | F37: =+'POR ALMACEN'!F382 | G37: 0 | H37: =+'POR ALMACEN'!P382 | I37: =H37-G37
B38: SAN ANDRES HIDALGO | C38: =+'POR ALMACEN'!C395 | D38: =+'POR ALMACEN'!D395 | E38: =+'POR ALMACEN'!E395 | F38: =+'POR ALMACEN'!F395 | G38: 0 | H38: =+'POR ALMACEN'!P395 | I38: =H38-G38
B39: SAN JOSE DEL CHILAR | C39: =+'POR ALMACEN'!C408 | D39: =+'POR ALMACEN'!D408 | E39: =+'POR ALMACEN'!E408 | F39: =+'POR ALMACEN'!F408 | G39: 0 | H39: =+'POR ALMACEN'!P408 | I39: =H39-G39
B40: TEOTITLAN DE FLORES MAGON | C40: =+'POR ALMACEN'!C423 | D40: =+'POR ALMACEN'!D423 | E40: =+'POR ALMACEN'!E423 | F40: =+'POR ALMACEN'!F423 | G40: 0 | H40: =+'POR ALMACEN'!P423 | I40: =H40-G40
B41: AYUTLA MIXES | C41: =+'POR ALMACEN'!C436 | D41: =+'POR ALMACEN'!D436 | E41: =+'POR ALMACEN'!E436 | F41: =+'POR ALMACEN'!F436 | G41: 0 | H41: =+'POR ALMACEN'!P436 | I41: =H41-G41
B42: IXTLAN DE JUAREZ | C42: =+'POR ALMACEN'!C456 | D42: =+'POR ALMACEN'!D456 | E42: =+'POR ALMACEN'!E456 | F42: =+'POR ALMACEN'!F456 | G42: 0 | H42: =+'POR ALMACEN'!P456 | I42: =H42-G42
B43: MAGDALENA OCOTLAN | C43: =+'POR ALMACEN'!C470 | D43: =+'POR ALMACEN'!D470 | E43: =+'POR ALMACEN'!E470 | F43: =+'POR ALMACEN'!F470 | G43: 0 | H43: =+'POR ALMACEN'!P470 | I43: =H43-G43
B44: SANTO TOMAS TAMAZULAPAN | C44: =+'POR ALMACEN'!C490 | D44: =+'POR ALMACEN'!D490 | E44: =+'POR ALMACEN'!E490 | F44: =+'POR ALMACEN'!F490 | G44: 0 | H44: =+'POR ALMACEN'!P490 | I44: =H44-G44
B45: SAN PEDRO JUCHATENGO | C45: =+'POR ALMACEN'!C506 | D45: =+'POR ALMACEN'!D506 | E45: =+'POR ALMACEN'!E506 | F45: =+'POR ALMACEN'!F506 | G45: 0 | H45: =+'POR ALMACEN'!P506 | I45: =H45-G45
B46: SANTA MARIA LACHIXIO | C46: =+'POR ALMACEN'!C517 | D46: =+'POR ALMACEN'!D517 | E46: =+'POR ALMACEN'!E517 | F46: =+'POR ALMACEN'!F517 | G46: 0 | H46: =+'POR ALMACEN'!P517 | I46: =H46-G46
B47: MATATLAN | C47: =+'POR ALMACEN'!C528 | D47: =+'POR ALMACEN'!D528 | E47: =+'POR ALMACEN'!E528 | F47: =+'POR ALMACEN'!F528 | G47: 0 | H47: =+'POR ALMACEN'!P528 | I47: =H47-G47
B48: CUAJIMOLOYAS | C48: =+'POR ALMACEN'!C541 | D48: =+'POR ALMACEN'!D541 | E48: =+'POR ALMACEN'!E541 | F48: =+'POR ALMACEN'!F541 | G48: 0 | H48: =+'POR ALMACEN'!P541 | I48: =H48-G48
...
